Not Found: /
[31/Jul/2017 10:57:55] "GET / HTTP/1.1" 404 2162
Not Found: /
[31/Jul/2017 10:57:58] "GET / HTTP/1.1" 404 2162
Not Found: /
[31/Jul/2017 10:57:59] "GET / HTTP/1.1" 404 2162
Not Found: /
[31/Jul/2017 10:58:02] "GET / HTTP/1.1" 404 2162
[31/Jul/2017 10:58:03] "GET /admin/ HTTP/1.1" 302 0
[31/Jul/2017 10:58:04] "GET /article/2/ HTTP/1.1" 200 49799
[31/Jul/2017 10:58:04] "GET /article/2/ HTTP/1.1" 200 49799
Not Found: /
[31/Jul/2017 10:58:08] "GET / HTTP/1.1" 404 2162
[31/Jul/2017 10:58:09] "GET /admin/ HTTP/1.1" 302 0
[31/Jul/2017 10:58:09] "GET /admin/login/?next=/admin/ HTTP/1.1" 200 1650
[31/Jul/2017 10:58:09] "GET /admin/ HTTP/1.1" 302 0
[31/Jul/2017 10:58:09] "GET /admin/login/?next=/admin/ HTTP/1.1" 200 1650
[31/Jul/2017 10:58:15] "POST /admin/login/?next=/admin/ HTTP/1.1" 302 0
[31/Jul/2017 10:58:15] "GET /admin/ HTTP/1.1" 200 5548
[31/Jul/2017 10:58:19] "GET /admin/article/article/ HTTP/1.1" 200 4647
[31/Jul/2017 10:58:19] "GET /admin/jsi18n/ HTTP/1.1" 200 3217
[31/Jul/2017 10:58:24] "POST /admin/article/article/ HTTP/1.1" 200 3450
[31/Jul/2017 10:58:24] "GET /static/admin/js/cancel.js HTTP/1.1" 304 0
[31/Jul/2017 10:58:25] "POST /admin/article/article/ HTTP/1.1" 302 0
[31/Jul/2017 10:58:25] "GET /admin/article/article/ HTTP/1.1" 200 3177
[31/Jul/2017 10:58:25] "GET /admin/jsi18n/ HTTP/1.1" 200 3217
[31/Jul/2017 10:58:27] "GET /admin/article/ HTTP/1.1" 200 2639
[31/Jul/2017 10:58:29] "GET /admin/article/article/add/ HTTP/1.1" 200 6998
[31/Jul/2017 10:58:29] "GET /admin/jsi18n/ HTTP/1.1" 200 3217
[31/Jul/2017 10:58:34] "POST /admin/article/article/add/ HTTP/1.1" 302 0
[31/Jul/2017 10:58:34] "GET /admin/article/article/ HTTP/1.1" 200 4367
[31/Jul/2017 10:58:34] "GET /admin/jsi18n/ HTTP/1.1" 200 3217
[31/Jul/2017 10:58:36] "GET /admin/article/article/6/change/ HTTP/1.1" 200 7227
[31/Jul/2017 10:58:36] "GET /admin/jsi18n/ HTTP/1.1" 200 3217
[31/Jul/2017 10:58:39] "GET /admin/article/ HTTP/1.1" 200 2639
[31/Jul/2017 10:58:40] "GET /admin/ HTTP/1.1" 200 6578
[31/Jul/2017 10:58:45] "GET /admin/article/category/add/ HTTP/1.1" 200 3835
[31/Jul/2017 10:58:45] "GET /admin/jsi18n/ HTTP/1.1" 200 3217
[31/Jul/2017 10:58:51] "POST /admin/article/category/add/ HTTP/1.1" 302 0
[31/Jul/2017 10:58:51] "GET /admin/article/category/ HTTP/1.1" 200 4606
[31/Jul/2017 10:58:52] "GET /admin/jsi18n/ HTTP/1.1" 200 3217
[31/Jul/2017 10:58:56] "POST /admin/article/category/ HTTP/1.1" 200 3279
[31/Jul/2017 10:58:58] "POST /admin/article/category/ HTTP/1.1" 302 0
[31/Jul/2017 10:58:58] "GET /admin/article/category/ HTTP/1.1" 200 4322
[31/Jul/2017 10:58:58] "GET /admin/jsi18n/ HTTP/1.1" 200 3217
[31/Jul/2017 10:59:01] "GET /admin/article/category/add/ HTTP/1.1" 200 3835
[31/Jul/2017 10:59:01] "GET /admin/jsi18n/ HTTP/1.1" 200 3217
[31/Jul/2017 10:59:04] "POST /admin/article/category/add/ HTTP/1.1" 302 0
[31/Jul/2017 10:59:05] "GET /admin/article/category/ HTTP/1.1" 200 4614
[31/Jul/2017 10:59:05] "GET /admin/jsi18n/ HTTP/1.1" 200 3217
[31/Jul/2017 10:59:06] "GET /admin/article/category/add/ HTTP/1.1" 200 3835
[31/Jul/2017 10:59:06] "GET /admin/jsi18n/ HTTP/1.1" 200 3217
[31/Jul/2017 10:59:10] "POST /admin/article/category/add/ HTTP/1.1" 302 0
[31/Jul/2017 10:59:10] "GET /admin/article/category/ HTTP/1.1" 200 4835
[31/Jul/2017 10:59:10] "GET /admin/jsi18n/ HTTP/1.1" 200 3217
[31/Jul/2017 10:59:12] "GET /admin/article/ HTTP/1.1" 200 2639
[31/Jul/2017 10:59:14] "GET /admin/ HTTP/1.1" 200 6568
[31/Jul/2017 10:59:16] "GET /admin/article/article/ HTTP/1.1" 200 3053
[31/Jul/2017 10:59:16] "GET /admin/jsi18n/ HTTP/1.1" 200 3217
[31/Jul/2017 10:59:18] "GET /admin/article/ HTTP/1.1" 200 2639
[31/Jul/2017 10:59:19] "GET /admin/ HTTP/1.1" 200 6568
Not Found: /
[31/Jul/2017 10:59:26] "GET / HTTP/1.1" 404 2162
Not Found: /
[31/Jul/2017 10:59:27] "GET / HTTP/1.1" 404 2162
[31/Jul/2017 10:59:28] "GET /admin/ HTTP/1.1" 200 6568
Internal Server Error: /article/2/
Traceback (most recent call last):
  File "/usr/lib/python2.7/site-packages/django/core/handlers/exception.py", line 41, in inner
    response = get_response(request)
  File "/usr/lib/python2.7/site-packages/django/core/handlers/base.py", line 187, in _get_response
    response = self.process_exception_by_middleware(e, request)
  File "/usr/lib/python2.7/site-packages/django/core/handlers/base.py", line 185, in _get_response
    response = wrapped_callback(request, *callback_args, **callback_kwargs)
  File "/volume1/homes/hcyuser/www/blog/article/views.py", line 14, in detail
    article = Article.objects.get(pk=int(pk))
  File "/usr/lib/python2.7/site-packages/django/db/models/manager.py", line 85, in manager_method
    return getattr(self.get_queryset(), name)(*args, **kwargs)
  File "/usr/lib/python2.7/site-packages/django/db/models/query.py", line 380, in get
    self.model._meta.object_name
DoesNotExist: Article matching query does not exist.
[31/Jul/2017 10:59:29] "GET /article/2/ HTTP/1.1" 500 69952
Internal Server Error: /article/2/
Traceback (most recent call last):
  File "/usr/lib/python2.7/site-packages/django/core/handlers/exception.py", line 41, in inner
    response = get_response(request)
  File "/usr/lib/python2.7/site-packages/django/core/handlers/base.py", line 187, in _get_response
    response = self.process_exception_by_middleware(e, request)
  File "/usr/lib/python2.7/site-packages/django/core/handlers/base.py", line 185, in _get_response
    response = wrapped_callback(request, *callback_args, **callback_kwargs)
  File "/volume1/homes/hcyuser/www/blog/article/views.py", line 14, in detail
    article = Article.objects.get(pk=int(pk))
  File "/usr/lib/python2.7/site-packages/django/db/models/manager.py", line 85, in manager_method
    return getattr(self.get_queryset(), name)(*args, **kwargs)
  File "/usr/lib/python2.7/site-packages/django/db/models/query.py", line 380, in get
    self.model._meta.object_name
DoesNotExist: Article matching query does not exist.
Not Found: /article/
[31/Jul/2017 10:59:31] "GET /article/2/ HTTP/1.1" 500 69952
[31/Jul/2017 10:59:31] "GET /article/ HTTP/1.1" 404 2204
[2017-07-31 10:59:31,785] - Broken pipe from ('192.168.1.1', 55570)

[31/Jul/2017 10:59:33] "GET /article/create/ HTTP/1.1" 200 945
[31/Jul/2017 10:59:34] "GET /article/create/ HTTP/1.1" 200 945
[31/Jul/2017 11:00:03] "POST /article/create/ HTTP/1.1" 302 0
[31/Jul/2017 11:00:03] "GET /article/7 HTTP/1.1" 301 0
[31/Jul/2017 11:00:03] "GET /article/7/ HTTP/1.1" 200 49758
[31/Jul/2017 11:00:23] "GET /admin/article/article/ HTTP/1.1" 200 4188
[31/Jul/2017 11:00:23] "GET /admin/jsi18n/ HTTP/1.1" 200 3217
[31/Jul/2017 11:00:25] "GET /admin/article/article/7/change/ HTTP/1.1" 200 7325
[31/Jul/2017 11:00:25] "GET /admin/jsi18n/ HTTP/1.1" 200 3217
[31/Jul/2017 11:00:35] "POST /admin/article/article/7/change/ HTTP/1.1" 302 0
[31/Jul/2017 11:00:36] "GET /admin/article/article/ HTTP/1.1" 200 4373
[31/Jul/2017 11:00:36] "GET /admin/jsi18n/ HTTP/1.1" 200 3217
[31/Jul/2017 11:00:38] "GET /admin/article/ HTTP/1.1" 200 2639
[31/Jul/2017 11:00:39] "GET /admin/ HTTP/1.1" 200 6606
[31/Jul/2017 11:00:43] "GET /admin/auth/ HTTP/1.1" 200 2707
[31/Jul/2017 11:00:44] "GET /admin/ HTTP/1.1" 200 6606
[31/Jul/2017 11:01:14] "GET /admin/article/article/ HTTP/1.1" 200 4188
[31/Jul/2017 11:01:14] "GET /admin/jsi18n/ HTTP/1.1" 200 3217
[31/Jul/2017 11:01:16] "GET /admin/article/article/7/change/ HTTP/1.1" 200 7325
[31/Jul/2017 11:01:16] "GET /admin/jsi18n/ HTTP/1.1" 200 3217
[31/Jul/2017 11:01:19] "GET /admin/article/ HTTP/1.1" 200 2639
[31/Jul/2017 11:01:20] "GET /admin/article/article/ HTTP/1.1" 200 4188
[31/Jul/2017 11:01:20] "GET /admin/jsi18n/ HTTP/1.1" 200 3217
[31/Jul/2017 11:01:23] "GET /admin/article/article/7/change/ HTTP/1.1" 200 7325
[31/Jul/2017 11:01:23] "GET /admin/jsi18n/ HTTP/1.1" 200 3217
[31/Jul/2017 11:01:25] "GET /admin/article/ HTTP/1.1" 200 2639
[31/Jul/2017 11:01:40] "POST /article/create/ HTTP/1.1" 302 0
[31/Jul/2017 11:01:40] "GET /article/8 HTTP/1.1" 301 0
[31/Jul/2017 11:01:40] "GET /article/8/ HTTP/1.1" 200 49755
[31/Jul/2017 11:02:40] "GET /article/1 HTTP/1.1" 301 0
Internal Server Error: /article/1/
Traceback (most recent call last):
  File "/usr/lib/python2.7/site-packages/django/core/handlers/exception.py", line 41, in inner
    response = get_response(request)
  File "/usr/lib/python2.7/site-packages/django/core/handlers/base.py", line 187, in _get_response
    response = self.process_exception_by_middleware(e, request)
  File "/usr/lib/python2.7/site-packages/django/core/handlers/base.py", line 185, in _get_response
    response = wrapped_callback(request, *callback_args, **callback_kwargs)
  File "/volume1/homes/hcyuser/www/blog/article/views.py", line 14, in detail
    article = Article.objects.get(pk=int(pk))
  File "/usr/lib/python2.7/site-packages/django/db/models/manager.py", line 85, in manager_method
    return getattr(self.get_queryset(), name)(*args, **kwargs)
  File "/usr/lib/python2.7/site-packages/django/db/models/query.py", line 380, in get
    self.model._meta.object_name
DoesNotExist: Article matching query does not exist.
[31/Jul/2017 11:02:41] "GET /article/1/ HTTP/1.1" 500 68570
Not Found: /favicon.ico
[31/Jul/2017 11:02:41] "GET /favicon.ico HTTP/1.1" 404 2213
[31/Jul/2017 11:02:47] "GET /admin/article/article/ HTTP/1.1" 200 4412
[31/Jul/2017 11:02:47] "GET /admin/jsi18n/ HTTP/1.1" 200 3217
[31/Jul/2017 11:02:49] "GET /admin/article/article/8/change/ HTTP/1.1" 200 7322
[31/Jul/2017 11:02:49] "GET /admin/jsi18n/ HTTP/1.1" 200 3217
[31/Jul/2017 11:02:54] "GET /article/8/ HTTP/1.1" 200 49755
Not Found: /favicon.ico
[31/Jul/2017 11:02:54] "GET /favicon.ico HTTP/1.1" 404 2213
[31/Jul/2017 11:04:00] "GET /admin/article/ HTTP/1.1" 200 2639
[31/Jul/2017 11:04:02] "GET /admin/article/article/ HTTP/1.1" 200 4412
[31/Jul/2017 11:04:02] "GET /admin/jsi18n/ HTTP/1.1" 200 3217
[31/Jul/2017 11:04:03] "GET /admin/article/article/8/change/ HTTP/1.1" 200 7322
[31/Jul/2017 11:04:03] "GET /admin/jsi18n/ HTTP/1.1" 200 3217
[31/Jul/2017 11:04:10] "GET /admin/article/article/ HTTP/1.1" 200 4412
[31/Jul/2017 11:04:10] "GET /admin/jsi18n/ HTTP/1.1" 200 3217
[31/Jul/2017 11:04:11] "GET /admin/article/ HTTP/1.1" 200 2639
[31/Jul/2017 11:04:12] "GET /admin/article/article/ HTTP/1.1" 200 4412
[31/Jul/2017 11:04:12] "GET /admin/jsi18n/ HTTP/1.1" 200 3217
[31/Jul/2017 11:04:16] "POST /admin/article/article/ HTTP/1.1" 200 3298
[31/Jul/2017 11:04:17] "POST /admin/article/article/ HTTP/1.1" 302 0
[31/Jul/2017 11:04:17] "GET /admin/article/article/ HTTP/1.1" 200 3177
[31/Jul/2017 11:04:17] "GET /admin/jsi18n/ HTTP/1.1" 200 3217
[31/Jul/2017 11:04:19] "GET /admin/logout/ HTTP/1.1" 200 1010
Not Found: /create
[31/Jul/2017 11:29:12] "GET /create HTTP/1.1" 404 2198
Not Found: /favicon.ico
[31/Jul/2017 11:29:13] "GET /favicon.ico HTTP/1.1" 404 2213
Not Found: /article
[31/Jul/2017 11:29:22] "GET /article HTTP/1.1" 404 2201
[31/Jul/2017 11:29:29] "GET /article/create HTTP/1.1" 301 0
[31/Jul/2017 11:29:29] "GET /article/create/ HTTP/1.1" 200 945
[31/Jul/2017 11:30:16] "POST /article/create/ HTTP/1.1" 302 0
[31/Jul/2017 11:30:16] "GET /article/9 HTTP/1.1" 301 0
[31/Jul/2017 11:30:16] "GET /article/9/ HTTP/1.1" 200 49739
[31/Jul/2017 11:30:45] "GET /admin HTTP/1.1" 301 0
[31/Jul/2017 11:30:45] "GET /admin/ HTTP/1.1" 200 6553
[31/Jul/2017 11:30:45] "GET /static/admin/css/dashboard.css HTTP/1.1" 304 0
[31/Jul/2017 11:30:45] "GET /static/admin/css/base.css HTTP/1.1" 304 0
[31/Jul/2017 11:30:45] "GET /static/admin/css/fonts.css HTTP/1.1" 304 0
[31/Jul/2017 11:30:45] "GET /static/admin/fonts/Roboto-Bold-webfont.woff HTTP/1.1" 304 0
[31/Jul/2017 11:30:45] "GET /static/admin/fonts/Roboto-Light-webfont.woff HTTP/1.1" 304 0
[31/Jul/2017 11:30:45] "GET /static/admin/fonts/Roboto-Regular-webfont.woff HTTP/1.1" 304 0
[31/Jul/2017 11:30:45] "GET /static/admin/img/icon-addlink.svg HTTP/1.1" 304 0
[31/Jul/2017 11:30:45] "GET /static/admin/img/icon-changelink.svg HTTP/1.1" 304 0
[31/Jul/2017 11:30:45] "GET /static/admin/img/icon-deletelink.svg HTTP/1.1" 200 392
[31/Jul/2017 11:30:51] "GET /admin/article/article/ HTTP/1.1" 200 4185
[31/Jul/2017 11:30:51] "GET /static/admin/css/changelists.css HTTP/1.1" 304 0
[31/Jul/2017 11:30:51] "GET /static/admin/js/core.js HTTP/1.1" 304 0
[31/Jul/2017 11:30:51] "GET /static/admin/js/jquery.init.js HTTP/1.1" 304 0
[31/Jul/2017 11:30:51] "GET /static/admin/js/vendor/jquery/jquery.js HTTP/1.1" 304 0
[31/Jul/2017 11:30:51] "GET /static/admin/js/admin/RelatedObjectLookups.js HTTP/1.1" 304 0
[31/Jul/2017 11:30:51] "GET /admin/jsi18n/ HTTP/1.1" 200 3217
[31/Jul/2017 11:30:51] "GET /static/admin/js/actions.js HTTP/1.1" 304 0
[31/Jul/2017 11:30:51] "GET /admin HTTP/1.1" 301 0
[31/Jul/2017 11:30:51] "GET /static/admin/js/urlify.js HTTP/1.1" 304 0
[31/Jul/2017 11:30:51] "GET /static/admin/js/vendor/xregexp/xregexp.js HTTP/1.1" 304 0
[31/Jul/2017 11:30:51] "GET /static/admin/js/prepopulate.js HTTP/1.1" 304 0
[31/Jul/2017 11:30:52] "GET /admin/ HTTP/1.1" 200 6553
[31/Jul/2017 11:30:52] "GET /static/admin/img/tooltag-add.svg HTTP/1.1" 304 0
[31/Jul/2017 11:30:53] "GET /admin/article/article/9/change/ HTTP/1.1" 200 7303
[31/Jul/2017 11:30:53] "GET /static/admin/css/forms.css HTTP/1.1" 304 0
[31/Jul/2017 11:30:54] "GET /static/admin/js/change_form.js HTTP/1.1" 304 0
[31/Jul/2017 11:30:54] "GET /static/admin/js/prepopulate_init.js HTTP/1.1" 304 0
[31/Jul/2017 11:30:54] "GET /admin/jsi18n/ HTTP/1.1" 200 3217
[31/Jul/2017 11:30:54] "GET /static/admin/css/widgets.css HTTP/1.1" 304 0
[31/Jul/2017 11:31:00] "POST /admin/article/article/9/change/ HTTP/1.1" 302 0
[31/Jul/2017 11:31:01] "GET /admin/article/article/ HTTP/1.1" 200 4367
[31/Jul/2017 11:31:01] "GET /admin/jsi18n/ HTTP/1.1" 200 3217
[31/Jul/2017 11:31:01] "GET /static/admin/img/icon-yes.svg HTTP/1.1" 304 0
[31/Jul/2017 11:31:10] "POST /admin/article/article/ HTTP/1.1" 200 3154
[31/Jul/2017 11:31:11] "GET /static/admin/js/cancel.js HTTP/1.1" 200 204
[31/Jul/2017 11:31:12] "POST /admin/article/article/ HTTP/1.1" 302 0
[31/Jul/2017 11:31:13] "GET /admin/article/article/ HTTP/1.1" 200 3176
[31/Jul/2017 11:31:13] "GET /admin/jsi18n/ HTTP/1.1" 200 3217
[31/Jul/2017 12:22:15] "GET /admin/ HTTP/1.1" 200 6589
Not Found: /favicon.ico
[31/Jul/2017 12:22:16] "GET /favicon.ico HTTP/1.1" 404 2213
[31/Jul/2017 12:22:21] "GET /admin/article/article/6/change/ HTTP/1.1" 302 0
[31/Jul/2017 12:22:21] "GET /admin/ HTTP/1.1" 200 6753
[31/Jul/2017 12:22:21] "GET /static/admin/img/icon-alert.svg HTTP/1.1" 200 504
[31/Jul/2017 12:22:28] "GET /admin/ HTTP/1.1" 200 6589
[31/Jul/2017 12:22:31] "GET /admin/ HTTP/1.1" 200 6589
[31/Jul/2017 12:22:34] "GET /admin/article/article/ HTTP/1.1" 200 3053
[31/Jul/2017 12:22:34] "GET /admin/jsi18n/ HTTP/1.1" 200 3217
[31/Jul/2017 12:22:37] "GET /admin/ HTTP/1.1" 200 6589
[31/Jul/2017 12:22:37] "GET /admin/article/article/ HTTP/1.1" 200 3053
[31/Jul/2017 12:22:38] "GET /admin/article/category/ HTTP/1.1" 200 4650
[31/Jul/2017 12:22:39] "GET /admin/jsi18n/ HTTP/1.1" 200 3217
[31/Jul/2017 12:22:40] "GET /admin/ HTTP/1.1" 200 6589
[31/Jul/2017 12:22:47] "GET /admin/logout/ HTTP/1.1" 200 1010
Not Found: /
[31/Jul/2017 13:45:51] "GET / HTTP/1.1" 404 2162
Not Found: /
[31/Jul/2017 13:45:51] "GET / HTTP/1.1" 404 2162
[31/Jul/2017 13:45:55] "GET /admin/ HTTP/1.1" 302 0
[31/Jul/2017 13:45:55] "GET /static/admin/css/fonts.css HTTP/1.1" 304 0
[31/Jul/2017 13:45:55] "GET /static/admin/css/login.css HTTP/1.1" 304 0
[31/Jul/2017 13:45:55] "GET /static/admin/css/base.css HTTP/1.1" 304 0
[31/Jul/2017 13:45:55] "GET /static/admin/fonts/Roboto-Light-webfont.woff HTTP/1.1" 304 0
[31/Jul/2017 13:45:55] "GET /static/admin/fonts/Roboto-Regular-webfont.woff HTTP/1.1" 304 0
[31/Jul/2017 13:45:55] "GET /admin/login/?next=/admin/ HTTP/1.1" 200 1650
[31/Jul/2017 13:45:56] "GET /admin/ HTTP/1.1" 302 0
[31/Jul/2017 13:45:56] "GET /admin/login/?next=/admin/ HTTP/1.1" 200 1650
Internal Server Error: /article/2/
Traceback (most recent call last):
  File "/usr/lib/python2.7/site-packages/django/core/handlers/exception.py", line 41, in inner
    response = get_response(request)
  File "/usr/lib/python2.7/site-packages/django/core/handlers/base.py", line 187, in _get_response
    response = self.process_exception_by_middleware(e, request)
  File "/usr/lib/python2.7/site-packages/django/core/handlers/base.py", line 185, in _get_response
    response = wrapped_callback(request, *callback_args, **callback_kwargs)
  File "/volume1/homes/hcyuser/www/blog/article/views.py", line 14, in detail
    article = Article.objects.get(pk=int(pk))
  File "/usr/lib/python2.7/site-packages/django/db/models/manager.py", line 85, in manager_method
    return getattr(self.get_queryset(), name)(*args, **kwargs)
  File "/usr/lib/python2.7/site-packages/django/db/models/query.py", line 380, in get
    self.model._meta.object_name
DoesNotExist: Article matching query does not exist.
[31/Jul/2017 13:46:02] "GET /article/2/ HTTP/1.1" 500 69758
Internal Server Error: /article/2/
Traceback (most recent call last):
  File "/usr/lib/python2.7/site-packages/django/core/handlers/exception.py", line 41, in inner
    response = get_response(request)
  File "/usr/lib/python2.7/site-packages/django/core/handlers/base.py", line 187, in _get_response
    response = self.process_exception_by_middleware(e, request)
  File "/usr/lib/python2.7/site-packages/django/core/handlers/base.py", line 185, in _get_response
    response = wrapped_callback(request, *callback_args, **callback_kwargs)
  File "/volume1/homes/hcyuser/www/blog/article/views.py", line 14, in detail
    article = Article.objects.get(pk=int(pk))
  File "/usr/lib/python2.7/site-packages/django/db/models/manager.py", line 85, in manager_method
    return getattr(self.get_queryset(), name)(*args, **kwargs)
  File "/usr/lib/python2.7/site-packages/django/db/models/query.py", line 380, in get
    self.model._meta.object_name
DoesNotExist: Article matching query does not exist.
[31/Jul/2017 13:46:03] "GET /article/2/ HTTP/1.1" 500 69758
Internal Server Error: /article/2/
Traceback (most recent call last):
  File "/usr/lib/python2.7/site-packages/django/core/handlers/exception.py", line 41, in inner
    response = get_response(request)
  File "/usr/lib/python2.7/site-packages/django/core/handlers/base.py", line 187, in _get_response
    response = self.process_exception_by_middleware(e, request)
  File "/usr/lib/python2.7/site-packages/django/core/handlers/base.py", line 185, in _get_response
    response = wrapped_callback(request, *callback_args, **callback_kwargs)
  File "/volume1/homes/hcyuser/www/blog/article/views.py", line 14, in detail
    article = Article.objects.get(pk=int(pk))
  File "/usr/lib/python2.7/site-packages/django/db/models/manager.py", line 85, in manager_method
    return getattr(self.get_queryset(), name)(*args, **kwargs)
  File "/usr/lib/python2.7/site-packages/django/db/models/query.py", line 380, in get
    self.model._meta.object_name
DoesNotExist: Article matching query does not exist.
Not Found: /article/
[31/Jul/2017 13:46:06] "GET /article/ HTTP/1.1" 404 2204
[31/Jul/2017 13:46:06] "GET /article/2/ HTTP/1.1" 500 69758
[31/Jul/2017 13:46:07] "GET /article/create/ HTTP/1.1" 200 945
[31/Jul/2017 13:46:08] "GET /article/create/ HTTP/1.1" 200 945
[31/Jul/2017 13:46:27] "GET /article/create/ HTTP/1.1" 200 945
Not Found: /
[31/Jul/2017 13:59:14] "GET / HTTP/1.1" 404 2162
Performing system checks...

System check identified no issues (0 silenced).
July 31, 2017 - 10:57:47
Django version 1.11.3, using settings 'blog.settings'
Starting development server at http://192.168.1.99:8000/
Quit the server with CONTROL-C.
Performing system checks...

System check identified no issues (0 silenced).
July 31, 2017 - 14:04:22
Django version 1.11.3, using settings 'blog.settings'
Starting development server at http://192.168.1.99:8000/
Quit the server with CONTROL-C.
Unhandled exception in thread started by <function wrapper at 0xb62a0aac>
Performing system checks...

Traceback (most recent call last):
  File "/usr/lib/python2.7/site-packages/django/utils/autoreload.py", line 227, in wrapper
    fn(*args, **kwargs)
  File "/usr/lib/python2.7/site-packages/django/core/management/commands/runserver.py", line 125, in inner_run
    self.check(display_num_errors=True)
  File "/usr/lib/python2.7/site-packages/django/core/management/base.py", line 359, in check
    include_deployment_checks=include_deployment_checks,
  File "/usr/lib/python2.7/site-packages/django/core/management/base.py", line 346, in _run_checks
    return checks.run_checks(**kwargs)
  File "/usr/lib/python2.7/site-packages/django/core/checks/registry.py", line 81, in run_checks
    new_errors = check(app_configs=app_configs)
  File "/usr/lib/python2.7/site-packages/django/core/checks/urls.py", line 16, in check_url_config
    return check_resolver(resolver)
  File "/usr/lib/python2.7/site-packages/django/core/checks/urls.py", line 26, in check_resolver
    return check_method()
  File "/usr/lib/python2.7/site-packages/django/urls/resolvers.py", line 254, in check
    for pattern in self.url_patterns:
  File "/usr/lib/python2.7/site-packages/django/utils/functional.py", line 35, in __get__
    res = instance.__dict__[self.name] = self.func(instance)
  File "/usr/lib/python2.7/site-packages/django/urls/resolvers.py", line 405, in url_patterns
    patterns = getattr(self.urlconf_module, "urlpatterns", self.urlconf_module)
  File "/usr/lib/python2.7/site-packages/django/utils/functional.py", line 35, in __get__
    res = instance.__dict__[self.name] = self.func(instance)
  File "/usr/lib/python2.7/site-packages/django/urls/resolvers.py", line 398, in urlconf_module
    return import_module(self.urlconf_name)
  File "/usr/lib/python2.7/importlib/__init__.py", line 37, in import_module
    __import__(name)
  File "/volume1/homes/hcyuser/www/blog/blog/urls.py", line 21, in <module>
    url(r'^grappelli/', include('grappelli.urls')),
NameError: name 'include' is not defined
Unhandled exception in thread started by <function wrapper at 0xb6336aac>
Performing system checks...

Traceback (most recent call last):
  File "/usr/lib/python2.7/site-packages/django/utils/autoreload.py", line 227, in wrapper
    fn(*args, **kwargs)
  File "/usr/lib/python2.7/site-packages/django/core/management/commands/runserver.py", line 125, in inner_run
    self.check(display_num_errors=True)
  File "/usr/lib/python2.7/site-packages/django/core/management/base.py", line 359, in check
    include_deployment_checks=include_deployment_checks,
  File "/usr/lib/python2.7/site-packages/django/core/management/base.py", line 346, in _run_checks
    return checks.run_checks(**kwargs)
  File "/usr/lib/python2.7/site-packages/django/core/checks/registry.py", line 81, in run_checks
    new_errors = check(app_configs=app_configs)
  File "/usr/lib/python2.7/site-packages/django/core/checks/urls.py", line 16, in check_url_config
    return check_resolver(resolver)
  File "/usr/lib/python2.7/site-packages/django/core/checks/urls.py", line 26, in check_resolver
    return check_method()
  File "/usr/lib/python2.7/site-packages/django/urls/resolvers.py", line 254, in check
    for pattern in self.url_patterns:
  File "/usr/lib/python2.7/site-packages/django/utils/functional.py", line 35, in __get__
    res = instance.__dict__[self.name] = self.func(instance)
  File "/usr/lib/python2.7/site-packages/django/urls/resolvers.py", line 405, in url_patterns
    patterns = getattr(self.urlconf_module, "urlpatterns", self.urlconf_module)
  File "/usr/lib/python2.7/site-packages/django/utils/functional.py", line 35, in __get__
    res = instance.__dict__[self.name] = self.func(instance)
  File "/usr/lib/python2.7/site-packages/django/urls/resolvers.py", line 398, in urlconf_module
    return import_module(self.urlconf_name)
  File "/usr/lib/python2.7/importlib/__init__.py", line 37, in import_module
    __import__(name)
  File "/volume1/homes/hcyuser/www/blog/blog/urls.py", line 21, in <module>
    url(r'^grappelli/', grappelli.urls),
NameError: name 'grappelli' is not defined
Not Found: /
[31/Jul/2017 14:07:26] "GET / HTTP/1.1" 404 2162
Not Found: /
[31/Jul/2017 14:07:27] "GET / HTTP/1.1" 404 2162
Not Found: /
[31/Jul/2017 14:07:47] "GET / HTTP/1.1" 404 2162
[31/Jul/2017 14:07:48] "GET /admin/login/?next=/admin/ HTTP/1.1" 200 5718
[31/Jul/2017 14:07:48] "GET /static/grappelli/jquery/ui/jquery-ui.min.css HTTP/1.1" 200 30163
[31/Jul/2017 14:07:48] "GET /static/grappelli/stylesheets/mueller/grid/output.css HTTP/1.1" 200 36537
[31/Jul/2017 14:07:48] "GET /static/grappelli/js/grappelli.min.js HTTP/1.1" 200 25791
[31/Jul/2017 14:07:48] "GET /static/grappelli/jquery/jquery.min.js HTTP/1.1" 200 85659
[31/Jul/2017 14:07:49] "GET /static/grappelli/jquery/ui/jquery-ui.min.js HTTP/1.1" 200 240427
[31/Jul/2017 14:07:49] "GET /static/grappelli/stylesheets/screen.css HTTP/1.1" 200 162373
[31/Jul/2017 14:07:49] "GET /admin HTTP/1.1" 301 0
[31/Jul/2017 14:07:49] "GET /admin/ HTTP/1.1" 302 0
[31/Jul/2017 14:07:49] "GET /admin/ HTTP/1.1" 302 0
[31/Jul/2017 14:07:49] "GET /admin/login/?next=/admin/ HTTP/1.1" 200 5718
[31/Jul/2017 14:07:49] "GET /static/grappelli/jquery/ui/jquery-ui.min.css HTTP/1.1" 200 30163
[31/Jul/2017 14:07:49] "GET /admin/login/?next=/admin/ HTTP/1.1" 200 5718
[31/Jul/2017 14:07:49] "GET /static/grappelli/stylesheets/screen.css HTTP/1.1" 200 162373
[31/Jul/2017 14:07:49] "GET /static/grappelli/stylesheets/screen.css HTTP/1.1" 200 162373
[31/Jul/2017 14:07:55] "POST /admin/login/?next=/admin/ HTTP/1.1" 302 0
[31/Jul/2017 14:07:55] "GET /admin/ HTTP/1.1" 200 13731
[31/Jul/2017 14:07:55] "GET /static/grappelli/images/icons-small-scbbb475e49.png HTTP/1.1" 200 926
[31/Jul/2017 14:08:03] "GET /static/admin/css/dashboard.css HTTP/1.1" 304 0
[31/Jul/2017 14:08:03] "GET /static/admin/img/icon-changelink.svg HTTP/1.1" 304 0
[31/Jul/2017 14:08:03] "GET /static/admin/fonts/Roboto-Bold-webfont.woff HTTP/1.1" 304 0
[31/Jul/2017 14:08:04] "GET /admin/article/ HTTP/1.1" 200 7390
[31/Jul/2017 14:08:04] "GET /static/grappelli/images/icons-s846f870921.png HTTP/1.1" 200 9306
[31/Jul/2017 14:08:05] "GET /admin/ HTTP/1.1" 200 13731
Internal Server Error: /admin/auth/group/add/
Traceback (most recent call last):
  File "/usr/lib/python2.7/site-packages/django/core/handlers/exception.py", line 41, in inner
    response = get_response(request)
  File "/usr/lib/python2.7/site-packages/django/core/handlers/base.py", line 217, in _get_response
    response = self.process_exception_by_middleware(e, request)
  File "/usr/lib/python2.7/site-packages/django/core/handlers/base.py", line 215, in _get_response
    response = response.render()
  File "/usr/lib/python2.7/site-packages/django/template/response.py", line 107, in render
    self.content = self.rendered_content
  File "/usr/lib/python2.7/site-packages/django/template/response.py", line 84, in rendered_content
    content = template.render(context, self._request)
  File "/usr/lib/python2.7/site-packages/django/template/backends/django.py", line 66, in render
    return self.template.render(context)
  File "/usr/lib/python2.7/site-packages/django/template/base.py", line 207, in render
    return self._render(context)
  File "/usr/lib/python2.7/site-packages/django/template/base.py", line 199, in _render
    return self.nodelist.render(context)
  File "/usr/lib/python2.7/site-packages/django/template/base.py", line 990, in render
    bit = node.render_annotated(context)
  File "/usr/lib/python2.7/site-packages/django/template/base.py", line 957, in render_annotated
    return self.render(context)
  File "/usr/lib/python2.7/site-packages/django/template/loader_tags.py", line 177, in render
    return compiled_parent._render(context)
  File "/usr/lib/python2.7/site-packages/django/template/base.py", line 199, in _render
    return self.nodelist.render(context)
  File "/usr/lib/python2.7/site-packages/django/template/base.py", line 990, in render
    bit = node.render_annotated(context)
  File "/usr/lib/python2.7/site-packages/django/template/base.py", line 957, in render_annotated
    return self.render(context)
  File "/usr/lib/python2.7/site-packages/django/template/loader_tags.py", line 177, in render
    return compiled_parent._render(context)
  File "/usr/lib/python2.7/site-packages/django/template/base.py", line 199, in _render
    return self.nodelist.render(context)
  File "/usr/lib/python2.7/site-packages/django/template/base.py", line 990, in render
    bit = node.render_annotated(context)
  File "/usr/lib/python2.7/site-packages/django/template/base.py", line 957, in render_annotated
    return self.render(context)
  File "/usr/lib/python2.7/site-packages/django/template/loader_tags.py", line 72, in render
    result = block.nodelist.render(context)
  File "/usr/lib/python2.7/site-packages/django/template/base.py", line 990, in render
    bit = node.render_annotated(context)
  File "/usr/lib/python2.7/site-packages/django/template/base.py", line 957, in render_annotated
    return self.render(context)
  File "/usr/lib/python2.7/site-packages/django/template/defaulttags.py", line 458, in render
    url = reverse(view_name, args=args, kwargs=kwargs, current_app=current_app)
  File "/usr/lib/python2.7/site-packages/django/urls/base.py", line 91, in reverse
    return force_text(iri_to_uri(resolver._reverse_with_prefix(view, prefix, *args, **kwargs)))
  File "/usr/lib/python2.7/site-packages/django/urls/resolvers.py", line 497, in _reverse_with_prefix
    raise NoReverseMatch(msg)
NoReverseMatch: Reverse for 'grp_related_lookup' not found. 'grp_related_lookup' is not a valid view function or pattern name.
[31/Jul/2017 14:08:10] "GET /admin/auth/group/add/ HTTP/1.1" 500 229293
[31/Jul/2017 14:08:18] "GET /admin/auth/group/ HTTP/1.1" 200 11134
[31/Jul/2017 14:08:18] "GET /static/grappelli/jquery/ui/jquery-ui.min.css HTTP/1.1" 304 0
[31/Jul/2017 14:08:18] "GET /static/grappelli/stylesheets/mueller/grid/output.css HTTP/1.1" 304 0
[31/Jul/2017 14:08:18] "GET /static/grappelli/jquery/jquery.min.js HTTP/1.1" 304 0
[31/Jul/2017 14:08:18] "GET /static/admin/js/admin/RelatedObjectLookups.js HTTP/1.1" 200 7351
[31/Jul/2017 14:08:18] "GET /static/grappelli/stylesheets/screen.css HTTP/1.1" 304 0
[31/Jul/2017 14:08:18] "GET /static/admin/js/vendor/jquery/jquery.js HTTP/1.1" 200 69
[31/Jul/2017 14:08:18] "GET /static/grappelli/js/grappelli.min.js HTTP/1.1" 304 0
[31/Jul/2017 14:08:18] "GET /static/grappelli/jquery/ui/jquery-ui.min.js HTTP/1.1" 304 0
[31/Jul/2017 14:08:18] "GET /static/admin/js/core.js HTTP/1.1" 200 7976
[31/Jul/2017 14:08:18] "GET /static/admin/js/actions.js HTTP/1.1" 200 6678
[31/Jul/2017 14:08:18] "GET /static/admin/js/jquery.init.js HTTP/1.1" 200 69
[31/Jul/2017 14:08:18] "GET /static/admin/js/urlify.js HTTP/1.1" 200 8186
[31/Jul/2017 14:08:18] "GET /admin/jsi18n/ HTTP/1.1" 200 3217
[31/Jul/2017 14:08:18] "GET /static/admin/js/prepopulate.js HTTP/1.1" 200 1535
[31/Jul/2017 14:08:19] "GET /static/admin/js/vendor/xregexp/xregexp.js HTTP/1.1" 200 128819
[31/Jul/2017 14:08:19] "GET /static/grappelli/images/icons/form-select.png HTTP/1.1" 200 289
[31/Jul/2017 14:08:22] "GET /static/admin/img/tooltag-add.svg HTTP/1.1" 304 0
[31/Jul/2017 14:08:22] "GET /static/admin/css/changelists.css HTTP/1.1" 304 0
[31/Jul/2017 14:08:22] "GET /static/admin/img/sorting-icons.svg HTTP/1.1" 304 0
[31/Jul/2017 14:08:22] "GET /static/admin/img/search.svg HTTP/1.1" 304 0
[31/Jul/2017 14:08:23] "GET /admin/auth/user/ HTTP/1.1" 200 16193
[31/Jul/2017 14:08:23] "GET /static/admin/img/icon-yes.svg HTTP/1.1" 200 436
[31/Jul/2017 14:08:23] "GET /admin/jsi18n/ HTTP/1.1" 200 3217
[31/Jul/2017 14:08:23] "GET /static/grappelli/images/backgrounds/changelist-results.png HTTP/1.1" 200 244
Not Found: /
[31/Jul/2017 14:08:52] "GET / HTTP/1.1" 404 2162
[31/Jul/2017 14:09:19] "GET /admin/ HTTP/1.1" 200 13731
Internal Server Error: /article/2/
Traceback (most recent call last):
  File "/usr/lib/python2.7/site-packages/django/core/handlers/exception.py", line 41, in inner
    response = get_response(request)
  File "/usr/lib/python2.7/site-packages/django/core/handlers/base.py", line 187, in _get_response
    response = self.process_exception_by_middleware(e, request)
  File "/usr/lib/python2.7/site-packages/django/core/handlers/base.py", line 185, in _get_response
    response = wrapped_callback(request, *callback_args, **callback_kwargs)
  File "/volume1/homes/hcyuser/www/blog/article/views.py", line 14, in detail
    article = Article.objects.get(pk=int(pk))
  File "/usr/lib/python2.7/site-packages/django/db/models/manager.py", line 85, in manager_method
    return getattr(self.get_queryset(), name)(*args, **kwargs)
  File "/usr/lib/python2.7/site-packages/django/db/models/query.py", line 380, in get
    self.model._meta.object_name
DoesNotExist: Article matching query does not exist.
[31/Jul/2017 14:09:20] "GET /article/2/ HTTP/1.1" 500 69999
Internal Server Error: /article/2/
Traceback (most recent call last):
  File "/usr/lib/python2.7/site-packages/django/core/handlers/exception.py", line 41, in inner
    response = get_response(request)
  File "/usr/lib/python2.7/site-packages/django/core/handlers/base.py", line 187, in _get_response
    response = self.process_exception_by_middleware(e, request)
  File "/usr/lib/python2.7/site-packages/django/core/handlers/base.py", line 185, in _get_response
    response = wrapped_callback(request, *callback_args, **callback_kwargs)
  File "/volume1/homes/hcyuser/www/blog/article/views.py", line 14, in detail
    article = Article.objects.get(pk=int(pk))
  File "/usr/lib/python2.7/site-packages/django/db/models/manager.py", line 85, in manager_method
    return getattr(self.get_queryset(), name)(*args, **kwargs)
  File "/usr/lib/python2.7/site-packages/django/db/models/query.py", line 380, in get
    self.model._meta.object_name
DoesNotExist: Article matching query does not exist.
[31/Jul/2017 14:09:24] "GET /article/2/ HTTP/1.1" 500 69999
Not Found: /article/
[31/Jul/2017 14:09:24] "GET /article/ HTTP/1.1" 404 2204
[31/Jul/2017 14:09:25] "GET /article/create/ HTTP/1.1" 200 945
[31/Jul/2017 14:09:25] "GET /article/create/ HTTP/1.1" 200 945
[31/Jul/2017 14:09:27] "GET /article/create/ HTTP/1.1" 200 945
[31/Jul/2017 14:10:26] "POST /article/create/ HTTP/1.1" 302 0
[31/Jul/2017 14:10:27] "GET /article/10 HTTP/1.1" 301 0
[31/Jul/2017 14:10:27] "GET /article/10/ HTTP/1.1" 200 49766
Internal Server Error: /article/2/
Traceback (most recent call last):
  File "/usr/lib/python2.7/site-packages/django/core/handlers/exception.py", line 41, in inner
    response = get_response(request)
  File "/usr/lib/python2.7/site-packages/django/core/handlers/base.py", line 187, in _get_response
    response = self.process_exception_by_middleware(e, request)
  File "/usr/lib/python2.7/site-packages/django/core/handlers/base.py", line 185, in _get_response
    response = wrapped_callback(request, *callback_args, **callback_kwargs)
  File "/volume1/homes/hcyuser/www/blog/article/views.py", line 14, in detail
    article = Article.objects.get(pk=int(pk))
  File "/usr/lib/python2.7/site-packages/django/db/models/manager.py", line 85, in manager_method
    return getattr(self.get_queryset(), name)(*args, **kwargs)
  File "/usr/lib/python2.7/site-packages/django/db/models/query.py", line 380, in get
    self.model._meta.object_name
DoesNotExist: Article matching query does not exist.
[31/Jul/2017 14:11:04] "GET /article/2/ HTTP/1.1" 500 70030
[31/Jul/2017 14:11:05] "GET /admin/ HTTP/1.1" 200 13731
[31/Jul/2017 14:11:05] "GET /static/grappelli/jquery/ui/jquery-ui.min.css HTTP/1.1" 304 0
[31/Jul/2017 14:11:05] "GET /static/grappelli/stylesheets/mueller/grid/output.css HTTP/1.1" 304 0
[31/Jul/2017 14:11:05] "GET /static/grappelli/js/grappelli.min.js HTTP/1.1" 304 0
[31/Jul/2017 14:11:05] "GET /static/grappelli/stylesheets/screen.css HTTP/1.1" 304 0
[31/Jul/2017 14:11:05] "GET /static/grappelli/jquery/jquery.min.js HTTP/1.1" 304 0
[31/Jul/2017 14:11:05] "GET /static/grappelli/jquery/ui/jquery-ui.min.js HTTP/1.1" 304 0
[31/Jul/2017 14:11:05] "GET /static/grappelli/images/icons-small-scbbb475e49.png HTTP/1.1" 304 0
Not Found: /
[31/Jul/2017 14:11:06] "GET / HTTP/1.1" 404 2162
Not Found: /
[31/Jul/2017 14:11:10] "GET / HTTP/1.1" 404 2162
[31/Jul/2017 14:11:11] "GET /admin/ HTTP/1.1" 200 13731
[31/Jul/2017 14:11:11] "GET /admin/ HTTP/1.1" 200 13731
[31/Jul/2017 14:11:11] "GET /static/grappelli/jquery/ui/jquery-ui.min.css HTTP/1.1" 304 0
[31/Jul/2017 14:11:11] "GET /static/grappelli/stylesheets/screen.css HTTP/1.1" 304 0
[31/Jul/2017 14:11:11] "GET /static/grappelli/stylesheets/mueller/grid/output.css HTTP/1.1" 304 0
[31/Jul/2017 14:11:11] "GET /static/grappelli/js/grappelli.min.js HTTP/1.1" 304 0
[31/Jul/2017 14:11:11] "GET /static/grappelli/jquery/jquery.min.js HTTP/1.1" 304 0
[31/Jul/2017 14:11:11] "GET /static/grappelli/jquery/ui/jquery-ui.min.js HTTP/1.1" 304 0
[31/Jul/2017 14:11:11] "GET /static/grappelli/images/icons-small-scbbb475e49.png HTTP/1.1" 304 0
[31/Jul/2017 14:11:14] "GET /admin/article/article/ HTTP/1.1" 200 11608
[31/Jul/2017 14:11:14] "GET /static/admin/js/admin/RelatedObjectLookups.js HTTP/1.1" 304 0
[31/Jul/2017 14:11:14] "GET /static/admin/js/jquery.init.js HTTP/1.1" 304 0
[31/Jul/2017 14:11:14] "GET /static/admin/js/vendor/jquery/jquery.js HTTP/1.1" 304 0
[31/Jul/2017 14:11:14] "GET /static/admin/js/urlify.js HTTP/1.1" 304 0
[31/Jul/2017 14:11:14] "GET /static/admin/js/core.js HTTP/1.1" 304 0
[31/Jul/2017 14:11:14] "GET /static/admin/js/actions.js HTTP/1.1" 304 0
[31/Jul/2017 14:11:14] "GET /static/admin/js/prepopulate.js HTTP/1.1" 304 0
[31/Jul/2017 14:11:14] "GET /static/admin/js/vendor/xregexp/xregexp.js HTTP/1.1" 304 0
[31/Jul/2017 14:11:14] "GET /admin/jsi18n/ HTTP/1.1" 200 3217
[31/Jul/2017 14:11:14] "GET /static/grappelli/images/icons-s846f870921.png HTTP/1.1" 304 0
[31/Jul/2017 14:11:14] "GET /static/grappelli/images/icons/form-select.png HTTP/1.1" 304 0
[31/Jul/2017 14:11:14] "GET /static/grappelli/images/backgrounds/changelist-results.png HTTP/1.1" 304 0
Internal Server Error: /admin/article/article/10/change/
Traceback (most recent call last):
  File "/usr/lib/python2.7/site-packages/django/core/handlers/exception.py", line 41, in inner
    response = get_response(request)
  File "/usr/lib/python2.7/site-packages/django/core/handlers/base.py", line 217, in _get_response
    response = self.process_exception_by_middleware(e, request)
  File "/usr/lib/python2.7/site-packages/django/core/handlers/base.py", line 215, in _get_response
    response = response.render()
  File "/usr/lib/python2.7/site-packages/django/template/response.py", line 107, in render
    self.content = self.rendered_content
  File "/usr/lib/python2.7/site-packages/django/template/response.py", line 84, in rendered_content
    content = template.render(context, self._request)
  File "/usr/lib/python2.7/site-packages/django/template/backends/django.py", line 66, in render
    return self.template.render(context)
  File "/usr/lib/python2.7/site-packages/django/template/base.py", line 207, in render
    return self._render(context)
  File "/usr/lib/python2.7/site-packages/django/template/base.py", line 199, in _render
    return self.nodelist.render(context)
  File "/usr/lib/python2.7/site-packages/django/template/base.py", line 990, in render
    bit = node.render_annotated(context)
  File "/usr/lib/python2.7/site-packages/django/template/base.py", line 957, in render_annotated
    return self.render(context)
  File "/usr/lib/python2.7/site-packages/django/template/loader_tags.py", line 177, in render
    return compiled_parent._render(context)
  File "/usr/lib/python2.7/site-packages/django/template/base.py", line 199, in _render
    return self.nodelist.render(context)
  File "/usr/lib/python2.7/site-packages/django/template/base.py", line 990, in render
    bit = node.render_annotated(context)
  File "/usr/lib/python2.7/site-packages/django/template/base.py", line 957, in render_annotated
    return self.render(context)
  File "/usr/lib/python2.7/site-packages/django/template/loader_tags.py", line 177, in render
    return compiled_parent._render(context)
  File "/usr/lib/python2.7/site-packages/django/template/base.py", line 199, in _render
    return self.nodelist.render(context)
  File "/usr/lib/python2.7/site-packages/django/template/base.py", line 990, in render
    bit = node.render_annotated(context)
  File "/usr/lib/python2.7/site-packages/django/template/base.py", line 957, in render_annotated
    return self.render(context)
  File "/usr/lib/python2.7/site-packages/django/template/loader_tags.py", line 72, in render
    result = block.nodelist.render(context)
  File "/usr/lib/python2.7/site-packages/django/template/base.py", line 990, in render
    bit = node.render_annotated(context)
  File "/usr/lib/python2.7/site-packages/django/template/base.py", line 957, in render_annotated
    return self.render(context)
  File "/usr/lib/python2.7/site-packages/django/template/defaulttags.py", line 458, in render
    url = reverse(view_name, args=args, kwargs=kwargs, current_app=current_app)
  File "/usr/lib/python2.7/site-packages/django/urls/base.py", line 91, in reverse
    return force_text(iri_to_uri(resolver._reverse_with_prefix(view, prefix, *args, **kwargs)))
  File "/usr/lib/python2.7/site-packages/django/urls/resolvers.py", line 497, in _reverse_with_prefix
    raise NoReverseMatch(msg)
NoReverseMatch: Reverse for 'grp_related_lookup' not found. 'grp_related_lookup' is not a valid view function or pattern name.
[31/Jul/2017 14:11:17] "GET /admin/article/article/10/change/ HTTP/1.1" 500 230353
Internal Server Error: /admin/article/article/10/change/
Traceback (most recent call last):
  File "/usr/lib/python2.7/site-packages/django/core/handlers/exception.py", line 41, in inner
    response = get_response(request)
  File "/usr/lib/python2.7/site-packages/django/core/handlers/base.py", line 217, in _get_response
    response = self.process_exception_by_middleware(e, request)
  File "/usr/lib/python2.7/site-packages/django/core/handlers/base.py", line 215, in _get_response
    response = response.render()
  File "/usr/lib/python2.7/site-packages/django/template/response.py", line 107, in render
    self.content = self.rendered_content
  File "/usr/lib/python2.7/site-packages/django/template/response.py", line 84, in rendered_content
    content = template.render(context, self._request)
  File "/usr/lib/python2.7/site-packages/django/template/backends/django.py", line 66, in render
    return self.template.render(context)
  File "/usr/lib/python2.7/site-packages/django/template/base.py", line 207, in render
    return self._render(context)
  File "/usr/lib/python2.7/site-packages/django/template/base.py", line 199, in _render
    return self.nodelist.render(context)
  File "/usr/lib/python2.7/site-packages/django/template/base.py", line 990, in render
    bit = node.render_annotated(context)
  File "/usr/lib/python2.7/site-packages/django/template/base.py", line 957, in render_annotated
    return self.render(context)
  File "/usr/lib/python2.7/site-packages/django/template/loader_tags.py", line 177, in render
    return compiled_parent._render(context)
  File "/usr/lib/python2.7/site-packages/django/template/base.py", line 199, in _render
    return self.nodelist.render(context)
  File "/usr/lib/python2.7/site-packages/django/template/base.py", line 990, in render
    bit = node.render_annotated(context)
  File "/usr/lib/python2.7/site-packages/django/template/base.py", line 957, in render_annotated
    return self.render(context)
  File "/usr/lib/python2.7/site-packages/django/template/loader_tags.py", line 177, in render
    return compiled_parent._render(context)
  File "/usr/lib/python2.7/site-packages/django/template/base.py", line 199, in _render
    return self.nodelist.render(context)
  File "/usr/lib/python2.7/site-packages/django/template/base.py", line 990, in render
    bit = node.render_annotated(context)
  File "/usr/lib/python2.7/site-packages/django/template/base.py", line 957, in render_annotated
    return self.render(context)
  File "/usr/lib/python2.7/site-packages/django/template/loader_tags.py", line 72, in render
    result = block.nodelist.render(context)
  File "/usr/lib/python2.7/site-packages/django/template/base.py", line 990, in render
    bit = node.render_annotated(context)
  File "/usr/lib/python2.7/site-packages/django/template/base.py", line 957, in render_annotated
    return self.render(context)
  File "/usr/lib/python2.7/site-packages/django/template/defaulttags.py", line 458, in render
    url = reverse(view_name, args=args, kwargs=kwargs, current_app=current_app)
  File "/usr/lib/python2.7/site-packages/django/urls/base.py", line 91, in reverse
    return force_text(iri_to_uri(resolver._reverse_with_prefix(view, prefix, *args, **kwargs)))
  File "/usr/lib/python2.7/site-packages/django/urls/resolvers.py", line 497, in _reverse_with_prefix
    raise NoReverseMatch(msg)
NoReverseMatch: Reverse for 'grp_related_lookup' not found. 'grp_related_lookup' is not a valid view function or pattern name.
[31/Jul/2017 14:11:24] "GET /admin/article/article/10/change/ HTTP/1.1" 500 230353
Performing system checks...

System check identified no issues (0 silenced).
July 31, 2017 - 14:07:25
Django version 1.11.3, using settings 'blog.settings'
Starting development server at http://192.168.1.99:8000/
Quit the server with CONTROL-C.
Performing system checks...

System check identified no issues (0 silenced).
July 31, 2017 - 14:11:45
Django version 1.11.3, using settings 'blog.settings'
Starting development server at http://192.168.1.99:8000/
Quit the server with CONTROL-C.
[31/Jul/2017 14:11:58] "GET /admin/article/article/ HTTP/1.1" 200 4198
[31/Jul/2017 14:11:59] "GET /static/admin/js/urlify.js HTTP/1.1" 304 0
[31/Jul/2017 14:11:59] "GET /static/admin/js/core.js HTTP/1.1" 304 0
[31/Jul/2017 14:11:59] "GET /static/admin/js/jquery.init.js HTTP/1.1" 304 0
[31/Jul/2017 14:11:59] "GET /static/admin/js/vendor/jquery/jquery.js HTTP/1.1" 304 0
[31/Jul/2017 14:11:59] "GET /static/admin/js/admin/RelatedObjectLookups.js HTTP/1.1" 304 0
[31/Jul/2017 14:11:59] "GET /admin/jsi18n/ HTTP/1.1" 200 3217
[31/Jul/2017 14:11:59] "GET /static/admin/js/actions.js HTTP/1.1" 304 0
[31/Jul/2017 14:11:59] "GET /static/admin/js/prepopulate.js HTTP/1.1" 304 0
[31/Jul/2017 14:11:59] "GET /static/admin/css/fonts.css HTTP/1.1" 200 423
[31/Jul/2017 14:11:59] "GET /static/admin/js/vendor/xregexp/xregexp.js HTTP/1.1" 304 0
[31/Jul/2017 14:11:59] "GET /static/admin/fonts/Roboto-Light-webfont.woff HTTP/1.1" 200 81348
[31/Jul/2017 14:12:02] "GET /admin/article/article/10/change/ HTTP/1.1" 200 7343
[31/Jul/2017 14:12:02] "GET /static/admin/js/change_form.js HTTP/1.1" 304 0
[31/Jul/2017 14:12:02] "GET /static/admin/js/prepopulate_init.js HTTP/1.1" 200 495
[31/Jul/2017 14:12:02] "GET /static/admin/css/forms.css HTTP/1.1" 304 0
[31/Jul/2017 14:12:02] "GET /admin/jsi18n/ HTTP/1.1" 200 3217
[31/Jul/2017 14:12:02] "GET /static/admin/img/icon-addlink.svg HTTP/1.1" 200 331
[31/Jul/2017 14:12:02] "GET /static/admin/css/widgets.css HTTP/1.1" 200 10340
[31/Jul/2017 14:12:20] "POST /admin/article/article/10/change/ HTTP/1.1" 302 0
[31/Jul/2017 14:12:21] "GET /admin/article/article/ HTTP/1.1" 200 4386
[31/Jul/2017 14:12:21] "GET /admin/jsi18n/ HTTP/1.1" 200 3217
[31/Jul/2017 14:12:24] "GET /admin/article/ HTTP/1.1" 200 2639
[31/Jul/2017 14:12:26] "GET /static/grappelli/jquery/ui/jquery-ui.min.css HTTP/1.1" 404 1729
[31/Jul/2017 14:12:26] "GET /static/grappelli/images/icons-small-scbbb475e49.png HTTP/1.1" 404 1750
[31/Jul/2017 14:12:26] "GET /static/grappelli/jquery/jquery.min.js HTTP/1.1" 404 1708
[31/Jul/2017 14:12:26] "GET /static/grappelli/js/grappelli.min.js HTTP/1.1" 404 1705
[31/Jul/2017 14:12:26] "GET /static/grappelli/stylesheets/mueller/grid/output.css HTTP/1.1" 404 1753
[31/Jul/2017 14:12:26] "GET /static/grappelli/jquery/ui/jquery-ui.min.js HTTP/1.1" 404 1726
[31/Jul/2017 14:12:26] "GET /static/grappelli/stylesheets/screen.css HTTP/1.1" 404 1714
[31/Jul/2017 14:12:26] "GET /admin/ HTTP/1.1" 200 6600
[31/Jul/2017 14:12:26] "GET /static/admin/img/icon-deletelink.svg HTTP/1.1" 304 0
Not Found: /
[31/Jul/2017 14:13:18] "GET / HTTP/1.1" 404 2162
[31/Jul/2017 14:13:22] "GET /admin/ HTTP/1.1" 200 6600
Internal Server Error: /article/2/
Traceback (most recent call last):
  File "/usr/lib/python2.7/site-packages/django/core/handlers/exception.py", line 41, in inner
    response = get_response(request)
  File "/usr/lib/python2.7/site-packages/django/core/handlers/base.py", line 187, in _get_response
    response = self.process_exception_by_middleware(e, request)
  File "/usr/lib/python2.7/site-packages/django/core/handlers/base.py", line 185, in _get_response
    response = wrapped_callback(request, *callback_args, **callback_kwargs)
  File "/volume1/homes/hcyuser/www/blog/article/views.py", line 14, in detail
    article = Article.objects.get(pk=int(pk))
  File "/usr/lib/python2.7/site-packages/django/db/models/manager.py", line 85, in manager_method
    return getattr(self.get_queryset(), name)(*args, **kwargs)
  File "/usr/lib/python2.7/site-packages/django/db/models/query.py", line 380, in get
    self.model._meta.object_name
DoesNotExist: Article matching query does not exist.
Internal Server Error: /article/2/
Traceback (most recent call last):
  File "/usr/lib/python2.7/site-packages/django/core/handlers/exception.py", line 41, in inner
    response = get_response(request)
  File "/usr/lib/python2.7/site-packages/django/core/handlers/base.py", line 187, in _get_response
    response = self.process_exception_by_middleware(e, request)
  File "/usr/lib/python2.7/site-packages/django/core/handlers/base.py", line 185, in _get_response
    response = wrapped_callback(request, *callback_args, **callback_kwargs)
  File "/volume1/homes/hcyuser/www/blog/article/views.py", line 14, in detail
    article = Article.objects.get(pk=int(pk))
  File "/usr/lib/python2.7/site-packages/django/db/models/manager.py", line 85, in manager_method
    return getattr(self.get_queryset(), name)(*args, **kwargs)
  File "/usr/lib/python2.7/site-packages/django/db/models/query.py", line 380, in get
    self.model._meta.object_name
DoesNotExist: Article matching query does not exist.
[31/Jul/2017 14:13:25] "GET /article/2/ HTTP/1.1" 500 69983
[31/Jul/2017 14:13:25] "GET /article/2/ HTTP/1.1" 500 69983
Internal Server Error: /article/1/
Traceback (most recent call last):
  File "/usr/lib/python2.7/site-packages/django/core/handlers/exception.py", line 41, in inner
    response = get_response(request)
  File "/usr/lib/python2.7/site-packages/django/core/handlers/base.py", line 187, in _get_response
    response = self.process_exception_by_middleware(e, request)
  File "/usr/lib/python2.7/site-packages/django/core/handlers/base.py", line 185, in _get_response
    response = wrapped_callback(request, *callback_args, **callback_kwargs)
  File "/volume1/homes/hcyuser/www/blog/article/views.py", line 14, in detail
    article = Article.objects.get(pk=int(pk))
  File "/usr/lib/python2.7/site-packages/django/db/models/manager.py", line 85, in manager_method
    return getattr(self.get_queryset(), name)(*args, **kwargs)
  File "/usr/lib/python2.7/site-packages/django/db/models/query.py", line 380, in get
    self.model._meta.object_name
DoesNotExist: Article matching query does not exist.
[31/Jul/2017 14:13:30] "GET /article/1/ HTTP/1.1" 500 69983
[31/Jul/2017 14:13:30] "GET /article/10/ HTTP/1.1" 200 49763
[31/Jul/2017 14:13:30] "GET /article/10/ HTTP/1.1" 200 49763
Performing system checks...

System check identified no issues (0 silenced).
July 31, 2017 - 14:11:57
Django version 1.11.3, using settings 'blog.settings'
Starting development server at http://192.168.1.99:8000/
Quit the server with CONTROL-C.
Performing system checks...

System check identified no issues (0 silenced).
July 31, 2017 - 14:20:33
Django version 1.11.3, using settings 'blog.settings'
Starting development server at http://192.168.1.99:8000/
Quit the server with CONTROL-C.
Performing system checks...

System check identified no issues (0 silenced).
July 31, 2017 - 14:22:22
Django version 1.11.3, using settings 'blog.settings'
Starting development server at http://192.168.1.99:8000/
Quit the server with CONTROL-C.
[31/Jul/2017 14:22:44] "GET /article/create/ HTTP/1.1" 200 945
[31/Jul/2017 14:22:48] "GET / HTTP/1.1" 200 12
Performing system checks...

System check identified no issues (0 silenced).
July 31, 2017 - 14:22:41
Django version 1.11.3, using settings 'blog.settings'
Starting development server at http://192.168.1.99:8000/
Quit the server with CONTROL-C.
Performing system checks...

System check identified no issues (0 silenced).
July 31, 2017 - 14:23:42
Django version 1.11.3, using settings 'blog.settings'
Starting development server at http://192.168.1.99:8000/
Quit the server with CONTROL-C.
Unhandled exception in thread started by <function wrapper at 0xb6272e2c>
Performing system checks...

Traceback (most recent call last):
  File "/usr/lib/python2.7/site-packages/django/utils/autoreload.py", line 227, in wrapper
    fn(*args, **kwargs)
  File "/usr/lib/python2.7/site-packages/django/core/management/commands/runserver.py", line 125, in inner_run
    self.check(display_num_errors=True)
  File "/usr/lib/python2.7/site-packages/django/core/management/base.py", line 405, in check
    raise SystemCheckError(msg)
django.core.management.base.SystemCheckError: SystemCheckError: System check identified some issues:

ERRORS:
cssapayment.Payment.category: (fields.E300) Field defines a relation with model 'Category', which is either not installed, or is abstract.
cssapayment.Payment.category: (fields.E307) The field cssapayment.Payment.category was declared with a lazy reference to 'cssapayment.category', but app 'cssapayment' doesn't provide model 'category'.

System check identified 2 issues (0 silenced).
Performing system checks...

System check identified no issues (0 silenced).
July 31, 2017 - 14:31:41
Django version 1.11.3, using settings 'blog.settings'
Starting development server at http://192.168.1.99:8000/
Quit the server with CONTROL-C.
Performing system checks...

System check identified no issues (0 silenced).
July 31, 2017 - 14:32:49
Django version 1.11.3, using settings 'blog.settings'
Starting development server at http://192.168.1.99:8000/
Quit the server with CONTROL-C.
Performing system checks...

System check identified no issues (0 silenced).
July 31, 2017 - 14:35:58
Django version 1.11.3, using settings 'blog.settings'
Starting development server at http://192.168.1.99:8000/
Quit the server with CONTROL-C.
Unhandled exception in thread started by <function wrapper at 0xb62efa74>
Traceback (most recent call last):
  File "/usr/lib/python2.7/site-packages/django/utils/autoreload.py", line 227, in wrapper
    fn(*args, **kwargs)
  File "/usr/lib/python2.7/site-packages/django/core/management/commands/runserver.py", line 117, in inner_run
    autoreload.raise_last_exception()
  File "/usr/lib/python2.7/site-packages/django/utils/autoreload.py", line 250, in raise_last_exception
    six.reraise(*_exception)
  File "/usr/lib/python2.7/site-packages/django/utils/autoreload.py", line 227, in wrapper
    fn(*args, **kwargs)
  File "/usr/lib/python2.7/site-packages/django/__init__.py", line 27, in setup
    apps.populate(settings.INSTALLED_APPS)
  File "/usr/lib/python2.7/site-packages/django/apps/registry.py", line 108, in populate
    app_config.import_models()
  File "/usr/lib/python2.7/site-packages/django/apps/config.py", line 202, in import_models
    self.models_module = import_module(models_module_name)
  File "/usr/lib/python2.7/importlib/__init__.py", line 37, in import_module
    __import__(name)
  File "/volume1/homes/hcyuser/www/blog/cssapayment/models.py", line 21
    ('7002', '中華郵政Chunghwa Post 無摺存款),
                                                     ^
SyntaxError: EOL while scanning string literal
Performing system checks...

System check identified no issues (0 silenced).
July 31, 2017 - 14:39:50
Django version 1.11.3, using settings 'blog.settings'
Starting development server at http://192.168.1.99:8000/
Quit the server with CONTROL-C.
Performing system checks...

System check identified no issues (0 silenced).
July 31, 2017 - 14:41:23
Django version 1.11.3, using settings 'blog.settings'
Starting development server at http://192.168.1.99:8000/
Quit the server with CONTROL-C.
Performing system checks...

System check identified no issues (0 silenced).
July 31, 2017 - 14:42:03
Django version 1.11.3, using settings 'blog.settings'
Starting development server at http://192.168.1.99:8000/
Quit the server with CONTROL-C.
Performing system checks...

System check identified no issues (0 silenced).
July 31, 2017 - 14:42:07
Django version 1.11.3, using settings 'blog.settings'
Starting development server at http://192.168.1.99:8000/
Quit the server with CONTROL-C.
Performing system checks...

System check identified no issues (0 silenced).
July 31, 2017 - 14:42:51
Django version 1.11.3, using settings 'blog.settings'
Starting development server at http://192.168.1.99:8000/
Quit the server with CONTROL-C.
Performing system checks...

System check identified no issues (0 silenced).
July 31, 2017 - 14:43:41
Django version 1.11.3, using settings 'blog.settings'
Starting development server at http://192.168.1.99:8000/
Quit the server with CONTROL-C.
Performing system checks...

System check identified no issues (0 silenced).
July 31, 2017 - 14:44:07
Django version 1.11.3, using settings 'blog.settings'
Starting development server at http://192.168.1.99:8000/
Quit the server with CONTROL-C.
Performing system checks...

System check identified no issues (0 silenced).
July 31, 2017 - 14:44:13
Django version 1.11.3, using settings 'blog.settings'
Starting development server at http://192.168.1.99:8000/
Quit the server with CONTROL-C.
Performing system checks...

System check identified no issues (0 silenced).
July 31, 2017 - 14:44:34
Django version 1.11.3, using settings 'blog.settings'
Starting development server at http://192.168.1.99:8000/
Quit the server with CONTROL-C.
Performing system checks...

System check identified no issues (0 silenced).
July 31, 2017 - 14:44:38
Django version 1.11.3, using settings 'blog.settings'
Starting development server at http://192.168.1.99:8000/
Quit the server with CONTROL-C.
Performing system checks...

System check identified no issues (0 silenced).
July 31, 2017 - 14:44:49
Django version 1.11.3, using settings 'blog.settings'
Starting development server at http://192.168.1.99:8000/
Quit the server with CONTROL-C.
Not Found: /
[31/Jul/2017 14:45:08] "GET / HTTP/1.1" 404 2162
Performing system checks...

System check identified no issues (0 silenced).
July 31, 2017 - 14:44:54
Django version 1.11.3, using settings 'blog.settings'
Starting development server at http://192.168.1.99:8000/
Quit the server with CONTROL-C.
Not Found: /
[31/Jul/2017 14:49:21] "GET / HTTP/1.1" 404 2162
Not Found: /
[31/Jul/2017 14:49:23] "GET / HTTP/1.1" 404 2162
[31/Jul/2017 14:49:24] "GET /admin/ HTTP/1.1" 200 7282
[31/Jul/2017 14:49:24] "GET /admin/ HTTP/1.1" 200 7282
[31/Jul/2017 14:49:25] "GET /admin/ HTTP/1.1" 200 7282
[31/Jul/2017 14:49:30] "GET /admin/cssapayment/payment/ HTTP/1.1" 200 3069
[31/Jul/2017 14:49:30] "GET /static/admin/js/vendor/jquery/jquery.js HTTP/1.1" 304 0
[31/Jul/2017 14:49:30] "GET /static/admin/js/jquery.init.js HTTP/1.1" 304 0
[31/Jul/2017 14:49:30] "GET /static/admin/js/admin/RelatedObjectLookups.js HTTP/1.1" 304 0
[31/Jul/2017 14:49:30] "GET /static/admin/js/actions.js HTTP/1.1" 304 0
[31/Jul/2017 14:49:30] "GET /static/admin/js/core.js HTTP/1.1" 304 0
[31/Jul/2017 14:49:30] "GET /admin/jsi18n/ HTTP/1.1" 200 3217
[31/Jul/2017 14:49:30] "GET /static/admin/js/urlify.js HTTP/1.1" 304 0
[31/Jul/2017 14:49:30] "GET /static/admin/js/prepopulate.js HTTP/1.1" 304 0
[31/Jul/2017 14:49:30] "GET /static/admin/js/vendor/xregexp/xregexp.js HTTP/1.1" 304 0
[31/Jul/2017 14:49:33] "GET /admin/cssapayment/payment/add/ HTTP/1.1" 200 6943
[31/Jul/2017 14:49:33] "GET /admin/jsi18n/ HTTP/1.1" 200 3217
[31/Jul/2017 14:49:49] "GET /admin/cssapayment/payment/ HTTP/1.1" 200 3069
[31/Jul/2017 14:49:49] "GET /admin/jsi18n/ HTTP/1.1" 200 3217
[31/Jul/2017 14:49:50] "GET /admin/cssapayment/ HTTP/1.1" 200 2272
[31/Jul/2017 14:49:52] "GET /admin/ HTTP/1.1" 200 7282
Performing system checks...

System check identified no issues (0 silenced).
July 31, 2017 - 14:49:18
Django version 1.11.3, using settings 'blog.settings'
Starting development server at http://192.168.1.99:8000/
Quit the server with CONTROL-C.
Unhandled exception in thread started by <function wrapper at 0xb6303ca4>
Performing system checks...

Traceback (most recent call last):
  File "/usr/lib/python2.7/site-packages/django/utils/autoreload.py", line 227, in wrapper
    fn(*args, **kwargs)
  File "/usr/lib/python2.7/site-packages/django/core/management/commands/runserver.py", line 125, in inner_run
    self.check(display_num_errors=True)
  File "/usr/lib/python2.7/site-packages/django/core/management/base.py", line 359, in check
    include_deployment_checks=include_deployment_checks,
  File "/usr/lib/python2.7/site-packages/django/core/management/base.py", line 346, in _run_checks
    return checks.run_checks(**kwargs)
  File "/usr/lib/python2.7/site-packages/django/core/checks/registry.py", line 81, in run_checks
    new_errors = check(app_configs=app_configs)
  File "/usr/lib/python2.7/site-packages/django/core/checks/urls.py", line 16, in check_url_config
    return check_resolver(resolver)
  File "/usr/lib/python2.7/site-packages/django/core/checks/urls.py", line 26, in check_resolver
    return check_method()
  File "/usr/lib/python2.7/site-packages/django/urls/resolvers.py", line 254, in check
    for pattern in self.url_patterns:
  File "/usr/lib/python2.7/site-packages/django/utils/functional.py", line 35, in __get__
    res = instance.__dict__[self.name] = self.func(instance)
  File "/usr/lib/python2.7/site-packages/django/urls/resolvers.py", line 405, in url_patterns
    patterns = getattr(self.urlconf_module, "urlpatterns", self.urlconf_module)
  File "/usr/lib/python2.7/site-packages/django/utils/functional.py", line 35, in __get__
    res = instance.__dict__[self.name] = self.func(instance)
  File "/usr/lib/python2.7/site-packages/django/urls/resolvers.py", line 398, in urlconf_module
    return import_module(self.urlconf_name)
  File "/usr/lib/python2.7/importlib/__init__.py", line 37, in import_module
    __import__(name)
  File "/volume1/homes/hcyuser/www/blog/blog/urls.py", line 20, in <module>
    from cssapayment.views import paymentdetail
  File "/volume1/homes/hcyuser/www/blog/cssapayment/views.py", line 6, in <module>
    from cssapayment.models import Article
ImportError: cannot import name Article
[31/Jul/2017 14:54:15] "GET /admin/ HTTP/1.1" 200 7282
[31/Jul/2017 14:54:22] "GET /admin/cssapayment/payment/add/ HTTP/1.1" 200 6943
[31/Jul/2017 14:54:22] "GET /static/admin/js/jquery.init.js HTTP/1.1" 304 0
[31/Jul/2017 14:54:22] "GET /static/admin/js/actions.js HTTP/1.1" 304 0
[31/Jul/2017 14:54:22] "GET /static/admin/js/core.js HTTP/1.1" 304 0
[31/Jul/2017 14:54:22] "GET /static/admin/js/admin/RelatedObjectLookups.js HTTP/1.1" 304 0
[31/Jul/2017 14:54:22] "GET /static/admin/js/vendor/jquery/jquery.js HTTP/1.1" 304 0
[31/Jul/2017 14:54:22] "GET /admin/jsi18n/ HTTP/1.1" 200 3217
[31/Jul/2017 14:54:22] "GET /static/admin/js/prepopulate.js HTTP/1.1" 304 0
[31/Jul/2017 14:54:22] "GET /static/admin/js/urlify.js HTTP/1.1" 304 0
[31/Jul/2017 14:54:22] "GET /static/admin/js/vendor/xregexp/xregexp.js HTTP/1.1" 304 0
Internal Server Error: /admin/cssapayment/payment/add/
Traceback (most recent call last):
  File "/usr/lib/python2.7/site-packages/django/core/handlers/exception.py", line 41, in inner
    response = get_response(request)
  File "/usr/lib/python2.7/site-packages/django/core/handlers/base.py", line 187, in _get_response
    response = self.process_exception_by_middleware(e, request)
  File "/usr/lib/python2.7/site-packages/django/core/handlers/base.py", line 185, in _get_response
    response = wrapped_callback(request, *callback_args, **callback_kwargs)
  File "/usr/lib/python2.7/site-packages/django/contrib/admin/options.py", line 551, in wrapper
    return self.admin_site.admin_view(view)(*args, **kwargs)
  File "/usr/lib/python2.7/site-packages/django/utils/decorators.py", line 149, in _wrapped_view
    response = view_func(request, *args, **kwargs)
  File "/usr/lib/python2.7/site-packages/django/views/decorators/cache.py", line 57, in _wrapped_view_func
    response = view_func(request, *args, **kwargs)
  File "/usr/lib/python2.7/site-packages/django/contrib/admin/sites.py", line 224, in inner
    return view(request, *args, **kwargs)
  File "/usr/lib/python2.7/site-packages/django/contrib/admin/options.py", line 1508, in add_view
    return self.changeform_view(request, None, form_url, extra_context)
  File "/usr/lib/python2.7/site-packages/django/utils/decorators.py", line 67, in _wrapper
    return bound_func(*args, **kwargs)
  File "/usr/lib/python2.7/site-packages/django/utils/decorators.py", line 149, in _wrapped_view
    response = view_func(request, *args, **kwargs)
  File "/usr/lib/python2.7/site-packages/django/utils/decorators.py", line 63, in bound_func
    return func.__get__(self, type(self))(*args2, **kwargs2)
  File "/usr/lib/python2.7/site-packages/django/contrib/admin/options.py", line 1408, in changeform_view
    return self._changeform_view(request, object_id, form_url, extra_context)
  File "/usr/lib/python2.7/site-packages/django/contrib/admin/options.py", line 1452, in _changeform_view
    self.log_addition(request, new_object, change_message)
  File "/usr/lib/python2.7/site-packages/django/contrib/admin/options.py", line 724, in log_addition
    object_repr=force_text(object),
  File "/usr/lib/python2.7/site-packages/django/utils/encoding.py", line 78, in force_text
    s = six.text_type(s)
  File "/volume1/homes/hcyuser/www/blog/cssapayment/models.py", line 34, in __unicode__
    return self.title
AttributeError: 'Payment' object has no attribute 'title'
[31/Jul/2017 14:54:58] "POST /admin/cssapayment/payment/add/ HTTP/1.1" 500 118574
[31/Jul/2017 14:55:30] "GET /admin/cssapayment/payment/ HTTP/1.1" 200 3069
[31/Jul/2017 14:55:30] "GET /admin/jsi18n/ HTTP/1.1" 200 3217
[31/Jul/2017 14:55:32] "GET /admin/cssapayment/payment/add/ HTTP/1.1" 200 6943
[31/Jul/2017 14:55:32] "GET /admin/jsi18n/ HTTP/1.1" 200 3217
Performing system checks...

System check identified no issues (0 silenced).
July 31, 2017 - 14:54:13
Django version 1.11.3, using settings 'blog.settings'
Starting development server at http://192.168.1.99:8000/
Quit the server with CONTROL-C.
Performing system checks...

System check identified no issues (0 silenced).
July 31, 2017 - 14:56:09
Django version 1.11.3, using settings 'blog.settings'
Starting development server at http://192.168.1.99:8000/
Quit the server with CONTROL-C.
Performing system checks...

System check identified no issues (0 silenced).
July 31, 2017 - 14:56:16
Django version 1.11.3, using settings 'blog.settings'
Starting development server at http://192.168.1.99:8000/
Quit the server with CONTROL-C.
Performing system checks...

System check identified no issues (0 silenced).
July 31, 2017 - 14:56:21
Django version 1.11.3, using settings 'blog.settings'
Starting development server at http://192.168.1.99:8000/
Quit the server with CONTROL-C.
Performing system checks...

System check identified no issues (0 silenced).
July 31, 2017 - 14:56:24
Django version 1.11.3, using settings 'blog.settings'
Starting development server at http://192.168.1.99:8000/
Quit the server with CONTROL-C.
[31/Jul/2017 14:56:41] "GET /admin/cssapayment/payment/ HTTP/1.1" 200 3069
[31/Jul/2017 14:56:41] "GET /admin/jsi18n/ HTTP/1.1" 200 3217
[31/Jul/2017 14:56:43] "GET /admin/cssapayment/payment/add/ HTTP/1.1" 200 6945
[31/Jul/2017 14:56:43] "GET /admin/jsi18n/ HTTP/1.1" 200 3217
Internal Server Error: /admin/cssapayment/payment/add/
Traceback (most recent call last):
  File "/usr/lib/python2.7/site-packages/django/core/handlers/exception.py", line 41, in inner
    response = get_response(request)
  File "/usr/lib/python2.7/site-packages/django/core/handlers/base.py", line 187, in _get_response
    response = self.process_exception_by_middleware(e, request)
  File "/usr/lib/python2.7/site-packages/django/core/handlers/base.py", line 185, in _get_response
    response = wrapped_callback(request, *callback_args, **callback_kwargs)
  File "/usr/lib/python2.7/site-packages/django/contrib/admin/options.py", line 551, in wrapper
    return self.admin_site.admin_view(view)(*args, **kwargs)
  File "/usr/lib/python2.7/site-packages/django/utils/decorators.py", line 149, in _wrapped_view
    response = view_func(request, *args, **kwargs)
  File "/usr/lib/python2.7/site-packages/django/views/decorators/cache.py", line 57, in _wrapped_view_func
    response = view_func(request, *args, **kwargs)
  File "/usr/lib/python2.7/site-packages/django/contrib/admin/sites.py", line 224, in inner
    return view(request, *args, **kwargs)
  File "/usr/lib/python2.7/site-packages/django/contrib/admin/options.py", line 1508, in add_view
    return self.changeform_view(request, None, form_url, extra_context)
  File "/usr/lib/python2.7/site-packages/django/utils/decorators.py", line 67, in _wrapper
    return bound_func(*args, **kwargs)
  File "/usr/lib/python2.7/site-packages/django/utils/decorators.py", line 149, in _wrapped_view
    response = view_func(request, *args, **kwargs)
  File "/usr/lib/python2.7/site-packages/django/utils/decorators.py", line 63, in bound_func
    return func.__get__(self, type(self))(*args2, **kwargs2)
  File "/usr/lib/python2.7/site-packages/django/contrib/admin/options.py", line 1408, in changeform_view
    return self._changeform_view(request, object_id, form_url, extra_context)
  File "/usr/lib/python2.7/site-packages/django/contrib/admin/options.py", line 1452, in _changeform_view
    self.log_addition(request, new_object, change_message)
  File "/usr/lib/python2.7/site-packages/django/contrib/admin/options.py", line 724, in log_addition
    object_repr=force_text(object),
  File "/usr/lib/python2.7/site-packages/django/utils/encoding.py", line 78, in force_text
    s = six.text_type(s)
  File "/volume1/homes/hcyuser/www/blog/cssapayment/models.py", line 34, in __unicode__
    return self.title
AttributeError: 'Payment' object has no attribute 'title'
[31/Jul/2017 14:57:08] "POST /admin/cssapayment/payment/add/ HTTP/1.1" 500 118572
Performing system checks...

System check identified no issues (0 silenced).
July 31, 2017 - 14:56:28
Django version 1.11.3, using settings 'blog.settings'
Starting development server at http://192.168.1.99:8000/
Quit the server with CONTROL-C.
Internal Server Error: /admin/cssapayment/payment/add/
Traceback (most recent call last):
  File "/usr/lib/python2.7/site-packages/django/core/handlers/exception.py", line 41, in inner
    response = get_response(request)
  File "/usr/lib/python2.7/site-packages/django/core/handlers/base.py", line 187, in _get_response
    response = self.process_exception_by_middleware(e, request)
  File "/usr/lib/python2.7/site-packages/django/core/handlers/base.py", line 185, in _get_response
    response = wrapped_callback(request, *callback_args, **callback_kwargs)
  File "/usr/lib/python2.7/site-packages/django/contrib/admin/options.py", line 551, in wrapper
    return self.admin_site.admin_view(view)(*args, **kwargs)
  File "/usr/lib/python2.7/site-packages/django/utils/decorators.py", line 149, in _wrapped_view
    response = view_func(request, *args, **kwargs)
  File "/usr/lib/python2.7/site-packages/django/views/decorators/cache.py", line 57, in _wrapped_view_func
    response = view_func(request, *args, **kwargs)
  File "/usr/lib/python2.7/site-packages/django/contrib/admin/sites.py", line 224, in inner
    return view(request, *args, **kwargs)
  File "/usr/lib/python2.7/site-packages/django/contrib/admin/options.py", line 1508, in add_view
    return self.changeform_view(request, None, form_url, extra_context)
  File "/usr/lib/python2.7/site-packages/django/utils/decorators.py", line 67, in _wrapper
    return bound_func(*args, **kwargs)
  File "/usr/lib/python2.7/site-packages/django/utils/decorators.py", line 149, in _wrapped_view
    response = view_func(request, *args, **kwargs)
  File "/usr/lib/python2.7/site-packages/django/utils/decorators.py", line 63, in bound_func
    return func.__get__(self, type(self))(*args2, **kwargs2)
  File "/usr/lib/python2.7/site-packages/django/contrib/admin/options.py", line 1408, in changeform_view
    return self._changeform_view(request, object_id, form_url, extra_context)
  File "/usr/lib/python2.7/site-packages/django/contrib/admin/options.py", line 1452, in _changeform_view
    self.log_addition(request, new_object, change_message)
  File "/usr/lib/python2.7/site-packages/django/contrib/admin/options.py", line 724, in log_addition
    object_repr=force_text(object),
  File "/usr/lib/python2.7/site-packages/django/utils/encoding.py", line 78, in force_text
    s = six.text_type(s)
  File "/volume1/homes/hcyuser/www/blog/cssapayment/models.py", line 34, in __unicode__
    return self.title
AttributeError: 'Payment' object has no attribute 'title'
[31/Jul/2017 14:57:46] "POST /admin/cssapayment/payment/add/ HTTP/1.1" 500 118572
Internal Server Error: /admin/cssapayment/payment/add/
Traceback (most recent call last):
  File "/usr/lib/python2.7/site-packages/django/core/handlers/exception.py", line 41, in inner
    response = get_response(request)
  File "/usr/lib/python2.7/site-packages/django/core/handlers/base.py", line 187, in _get_response
    response = self.process_exception_by_middleware(e, request)
  File "/usr/lib/python2.7/site-packages/django/core/handlers/base.py", line 185, in _get_response
    response = wrapped_callback(request, *callback_args, **callback_kwargs)
  File "/usr/lib/python2.7/site-packages/django/contrib/admin/options.py", line 551, in wrapper
    return self.admin_site.admin_view(view)(*args, **kwargs)
  File "/usr/lib/python2.7/site-packages/django/utils/decorators.py", line 149, in _wrapped_view
    response = view_func(request, *args, **kwargs)
  File "/usr/lib/python2.7/site-packages/django/views/decorators/cache.py", line 57, in _wrapped_view_func
    response = view_func(request, *args, **kwargs)
  File "/usr/lib/python2.7/site-packages/django/contrib/admin/sites.py", line 224, in inner
    return view(request, *args, **kwargs)
  File "/usr/lib/python2.7/site-packages/django/contrib/admin/options.py", line 1508, in add_view
    return self.changeform_view(request, None, form_url, extra_context)
  File "/usr/lib/python2.7/site-packages/django/utils/decorators.py", line 67, in _wrapper
    return bound_func(*args, **kwargs)
  File "/usr/lib/python2.7/site-packages/django/utils/decorators.py", line 149, in _wrapped_view
    response = view_func(request, *args, **kwargs)
  File "/usr/lib/python2.7/site-packages/django/utils/decorators.py", line 63, in bound_func
    return func.__get__(self, type(self))(*args2, **kwargs2)
  File "/usr/lib/python2.7/site-packages/django/contrib/admin/options.py", line 1408, in changeform_view
    return self._changeform_view(request, object_id, form_url, extra_context)
  File "/usr/lib/python2.7/site-packages/django/contrib/admin/options.py", line 1452, in _changeform_view
    self.log_addition(request, new_object, change_message)
  File "/usr/lib/python2.7/site-packages/django/contrib/admin/options.py", line 724, in log_addition
    object_repr=force_text(object),
  File "/usr/lib/python2.7/site-packages/django/utils/encoding.py", line 78, in force_text
    s = six.text_type(s)
  File "/volume1/homes/hcyuser/www/blog/cssapayment/models.py", line 34, in __unicode__
    return self.title
AttributeError: 'Payment' object has no attribute 'title'
[31/Jul/2017 14:58:03] "POST /admin/cssapayment/payment/add/ HTTP/1.1" 500 118572
Internal Server Error: /admin/cssapayment/payment/add/
Traceback (most recent call last):
  File "/usr/lib/python2.7/site-packages/django/core/handlers/exception.py", line 41, in inner
    response = get_response(request)
  File "/usr/lib/python2.7/site-packages/django/core/handlers/base.py", line 187, in _get_response
    response = self.process_exception_by_middleware(e, request)
  File "/usr/lib/python2.7/site-packages/django/core/handlers/base.py", line 185, in _get_response
    response = wrapped_callback(request, *callback_args, **callback_kwargs)
  File "/usr/lib/python2.7/site-packages/django/contrib/admin/options.py", line 551, in wrapper
    return self.admin_site.admin_view(view)(*args, **kwargs)
  File "/usr/lib/python2.7/site-packages/django/utils/decorators.py", line 149, in _wrapped_view
    response = view_func(request, *args, **kwargs)
  File "/usr/lib/python2.7/site-packages/django/views/decorators/cache.py", line 57, in _wrapped_view_func
    response = view_func(request, *args, **kwargs)
  File "/usr/lib/python2.7/site-packages/django/contrib/admin/sites.py", line 224, in inner
    return view(request, *args, **kwargs)
  File "/usr/lib/python2.7/site-packages/django/contrib/admin/options.py", line 1508, in add_view
    return self.changeform_view(request, None, form_url, extra_context)
  File "/usr/lib/python2.7/site-packages/django/utils/decorators.py", line 67, in _wrapper
    return bound_func(*args, **kwargs)
  File "/usr/lib/python2.7/site-packages/django/utils/decorators.py", line 149, in _wrapped_view
    response = view_func(request, *args, **kwargs)
  File "/usr/lib/python2.7/site-packages/django/utils/decorators.py", line 63, in bound_func
    return func.__get__(self, type(self))(*args2, **kwargs2)
  File "/usr/lib/python2.7/site-packages/django/contrib/admin/options.py", line 1408, in changeform_view
    return self._changeform_view(request, object_id, form_url, extra_context)
  File "/usr/lib/python2.7/site-packages/django/contrib/admin/options.py", line 1452, in _changeform_view
    self.log_addition(request, new_object, change_message)
  File "/usr/lib/python2.7/site-packages/django/contrib/admin/options.py", line 724, in log_addition
    object_repr=force_text(object),
  File "/usr/lib/python2.7/site-packages/django/utils/encoding.py", line 78, in force_text
    s = six.text_type(s)
  File "/volume1/homes/hcyuser/www/blog/cssapayment/models.py", line 34, in __unicode__
    return self.title
AttributeError: 'Payment' object has no attribute 'title'
[31/Jul/2017 14:58:09] "POST /admin/cssapayment/payment/add/ HTTP/1.1" 500 118594
[31/Jul/2017 14:58:14] "GET /admin/cssapayment/payment/ HTTP/1.1" 200 3069
[31/Jul/2017 14:58:14] "GET /admin/jsi18n/ HTTP/1.1" 200 3217
Performing system checks...

System check identified no issues (0 silenced).
July 31, 2017 - 14:57:45
Django version 1.11.3, using settings 'blog.settings'
Starting development server at http://192.168.1.99:8000/
Quit the server with CONTROL-C.
[31/Jul/2017 14:58:52] "GET /admin/cssapayment/payment/add/ HTTP/1.1" 200 6945
[31/Jul/2017 14:58:53] "GET /admin/jsi18n/ HTTP/1.1" 200 3217
[31/Jul/2017 14:59:20] "POST /admin/cssapayment/payment/add/ HTTP/1.1" 302 0
[31/Jul/2017 14:59:20] "GET /admin/cssapayment/payment/ HTTP/1.1" 200 4387
[31/Jul/2017 14:59:20] "GET /admin/jsi18n/ HTTP/1.1" 200 3217
[31/Jul/2017 14:59:25] "GET /admin/cssapayment/payment/1/change/ HTTP/1.1" 200 7204
[31/Jul/2017 14:59:25] "GET /admin/jsi18n/ HTTP/1.1" 200 3217
[31/Jul/2017 14:59:29] "POST /admin/cssapayment/payment/1/change/ HTTP/1.1" 302 0
[31/Jul/2017 14:59:30] "GET /admin/cssapayment/payment/ HTTP/1.1" 200 4399
[31/Jul/2017 14:59:30] "GET /static/admin/js/vendor/jquery/jquery.js HTTP/1.1" 304 0
[31/Jul/2017 14:59:30] "GET /static/admin/js/core.js HTTP/1.1" 304 0
[31/Jul/2017 14:59:30] "GET /static/admin/js/urlify.js HTTP/1.1" 304 0
[31/Jul/2017 14:59:30] "GET /static/admin/js/admin/RelatedObjectLookups.js HTTP/1.1" 304 0
[31/Jul/2017 14:59:30] "GET /static/admin/js/jquery.init.js HTTP/1.1" 304 0
[31/Jul/2017 14:59:30] "GET /admin/jsi18n/ HTTP/1.1" 200 3217
[31/Jul/2017 14:59:30] "GET /static/admin/js/actions.js HTTP/1.1" 304 0
[31/Jul/2017 14:59:30] "GET /static/admin/js/prepopulate.js HTTP/1.1" 304 0
[31/Jul/2017 14:59:30] "GET /static/admin/js/vendor/xregexp/xregexp.js HTTP/1.1" 304 0
Performing system checks...

System check identified no issues (0 silenced).
July 31, 2017 - 14:58:51
Django version 1.11.3, using settings 'blog.settings'
Starting development server at http://192.168.1.99:8000/
Quit the server with CONTROL-C.
[31/Jul/2017 14:59:44] "GET /admin/cssapayment/payment/ HTTP/1.1" 200 4204
[31/Jul/2017 14:59:45] "GET /static/admin/css/changelists.css HTTP/1.1" 304 0
[31/Jul/2017 14:59:45] "GET /static/admin/css/base.css HTTP/1.1" 304 0
[31/Jul/2017 14:59:45] "GET /static/admin/js/jquery.init.js HTTP/1.1" 304 0
[31/Jul/2017 14:59:45] "GET /static/admin/js/vendor/jquery/jquery.js HTTP/1.1" 304 0
[31/Jul/2017 14:59:45] "GET /static/admin/js/core.js HTTP/1.1" 304 0
[31/Jul/2017 14:59:45] "GET /admin/jsi18n/ HTTP/1.1" 200 3217
[31/Jul/2017 14:59:45] "GET /static/admin/js/actions.js HTTP/1.1" 304 0
[31/Jul/2017 14:59:45] "GET /static/admin/js/admin/RelatedObjectLookups.js HTTP/1.1" 304 0
[31/Jul/2017 14:59:45] "GET /static/admin/css/fonts.css HTTP/1.1" 304 0
[31/Jul/2017 14:59:45] "GET /static/admin/js/urlify.js HTTP/1.1" 304 0
[31/Jul/2017 14:59:45] "GET /static/admin/js/prepopulate.js HTTP/1.1" 304 0
[31/Jul/2017 14:59:45] "GET /static/admin/js/vendor/xregexp/xregexp.js HTTP/1.1" 304 0
[31/Jul/2017 14:59:45] "GET /static/admin/img/tooltag-add.svg HTTP/1.1" 304 0
[31/Jul/2017 14:59:45] "GET /static/admin/fonts/Roboto-Light-webfont.woff HTTP/1.1" 304 0
[31/Jul/2017 14:59:45] "GET /static/admin/fonts/Roboto-Regular-webfont.woff HTTP/1.1" 304 0
[31/Jul/2017 14:59:45] "GET /static/admin/fonts/Roboto-Bold-webfont.woff HTTP/1.1" 304 0
[31/Jul/2017 14:59:46] "GET /admin/cssapayment/payment/1/change/ HTTP/1.1" 200 7209
[31/Jul/2017 14:59:46] "GET /admin/jsi18n/ HTTP/1.1" 200 3217
[31/Jul/2017 15:00:07] "POST /admin/cssapayment/payment/1/change/ HTTP/1.1" 302 0
[31/Jul/2017 15:00:08] "GET /admin/cssapayment/payment/ HTTP/1.1" 200 4403
[31/Jul/2017 15:00:08] "GET /admin/jsi18n/ HTTP/1.1" 200 3217
Performing system checks...

System check identified no issues (0 silenced).
July 31, 2017 - 14:59:40
Django version 1.11.3, using settings 'blog.settings'
Starting development server at http://192.168.1.99:8000/
Quit the server with CONTROL-C.
Performing system checks...

System check identified no issues (0 silenced).
July 31, 2017 - 15:00:15
Django version 1.11.3, using settings 'blog.settings'
Starting development server at http://192.168.1.99:8000/
Quit the server with CONTROL-C.
Performing system checks...

System check identified no issues (0 silenced).
July 31, 2017 - 15:00:27
Django version 1.11.3, using settings 'blog.settings'
Starting development server at http://192.168.1.99:8000/
Quit the server with CONTROL-C.
Performing system checks...

System check identified no issues (0 silenced).
July 31, 2017 - 15:00:31
Django version 1.11.3, using settings 'blog.settings'
Starting development server at http://192.168.1.99:8000/
Quit the server with CONTROL-C.
Performing system checks...

System check identified no issues (0 silenced).
July 31, 2017 - 15:00:37
Django version 1.11.3, using settings 'blog.settings'
Starting development server at http://192.168.1.99:8000/
Quit the server with CONTROL-C.
Performing system checks...

System check identified no issues (0 silenced).
July 31, 2017 - 15:00:41
Django version 1.11.3, using settings 'blog.settings'
Starting development server at http://192.168.1.99:8000/
Quit the server with CONTROL-C.
Performing system checks...

System check identified no issues (0 silenced).
July 31, 2017 - 15:00:44
Django version 1.11.3, using settings 'blog.settings'
Starting development server at http://192.168.1.99:8000/
Quit the server with CONTROL-C.
Not Found: /payment/
[31/Jul/2017 15:01:44] "GET /payment/ HTTP/1.1" 404 2335
[31/Jul/2017 15:01:46] "GET /payment/3 HTTP/1.1" 301 0
Internal Server Error: /payment/3/
Traceback (most recent call last):
  File "/usr/lib/python2.7/site-packages/django/core/handlers/exception.py", line 41, in inner
    response = get_response(request)
  File "/usr/lib/python2.7/site-packages/django/core/handlers/base.py", line 187, in _get_response
    response = self.process_exception_by_middleware(e, request)
  File "/usr/lib/python2.7/site-packages/django/core/handlers/base.py", line 185, in _get_response
    response = wrapped_callback(request, *callback_args, **callback_kwargs)
  File "/volume1/homes/hcyuser/www/blog/cssapayment/views.py", line 9, in paymentdetail
    pay = Payment.objects.get(pk=int(pk))
  File "/usr/lib/python2.7/site-packages/django/db/models/manager.py", line 85, in manager_method
    return getattr(self.get_queryset(), name)(*args, **kwargs)
  File "/usr/lib/python2.7/site-packages/django/db/models/query.py", line 380, in get
    self.model._meta.object_name
DoesNotExist: Payment matching query does not exist.
[31/Jul/2017 15:01:47] "GET /payment/3/ HTTP/1.1" 500 69953
[31/Jul/2017 15:01:52] "GET /admin/cssapayment/payment/1/change/ HTTP/1.1" 200 7225
[31/Jul/2017 15:01:52] "GET /admin/jsi18n/ HTTP/1.1" 200 3217
[31/Jul/2017 15:01:56] "GET /admin/cssapayment/payment/1/change/ HTTP/1.1" 200 7225
[31/Jul/2017 15:01:56] "GET /admin/jsi18n/ HTTP/1.1" 200 3217
[31/Jul/2017 15:02:01] "GET /payment/1/ HTTP/1.1" 200 106
Performing system checks...

System check identified no issues (0 silenced).
July 31, 2017 - 15:00:51
Django version 1.11.3, using settings 'blog.settings'
Starting development server at http://192.168.1.99:8000/
Quit the server with CONTROL-C.
Performing system checks...

System check identified no issues (0 silenced).
July 31, 2017 - 15:06:18
Django version 1.11.3, using settings 'blog.settings'
Starting development server at http://192.168.1.99:8000/
Quit the server with CONTROL-C.
Not Found: /
[31/Jul/2017 15:09:54] "GET / HTTP/1.1" 404 2293
Not Found: /
[31/Jul/2017 15:09:56] "GET / HTTP/1.1" 404 2293
[31/Jul/2017 15:09:59] "GET /payment/1/ HTTP/1.1" 200 49723
[31/Jul/2017 15:10:00] "GET /payment/1/ HTTP/1.1" 200 49723
Performing system checks...

System check identified no issues (0 silenced).
July 31, 2017 - 15:06:48
Django version 1.11.3, using settings 'blog.settings'
Starting development server at http://192.168.1.99:8000/
Quit the server with CONTROL-C.
Not Found: /
[31/Jul/2017 15:11:24] "GET / HTTP/1.1" 404 2293
Not Found: /
[31/Jul/2017 15:11:26] "GET / HTTP/1.1" 404 2293
Not Found: /
[31/Jul/2017 15:11:28] "GET / HTTP/1.1" 404 2293
Not Found: /
[31/Jul/2017 15:11:30] "GET / HTTP/1.1" 404 2293
Not Found: /
[31/Jul/2017 15:11:31] "GET / HTTP/1.1" 404 2293
[31/Jul/2017 15:11:31] "GET /payment/1/ HTTP/1.1" 200 144
[31/Jul/2017 15:11:32] "GET /payment/1/ HTTP/1.1" 200 144
[31/Jul/2017 15:12:19] "GET /payment/1/ HTTP/1.1" 200 164
[31/Jul/2017 15:12:20] "GET /payment/1/ HTTP/1.1" 200 164
Performing system checks...

System check identified no issues (0 silenced).
July 31, 2017 - 15:11:24
Django version 1.11.3, using settings 'blog.settings'
Starting development server at http://192.168.1.99:8000/
Quit the server with CONTROL-C.
Performing system checks...

System check identified no issues (0 silenced).
July 31, 2017 - 15:13:23
Django version 1.11.3, using settings 'blog.settings'
Starting development server at http://192.168.1.99:8000/
Quit the server with CONTROL-C.
Unhandled exception in thread started by <function wrapper at 0xb62e2ca4>
Performing system checks...

Traceback (most recent call last):
  File "/usr/lib/python2.7/site-packages/django/utils/autoreload.py", line 227, in wrapper
    fn(*args, **kwargs)
  File "/usr/lib/python2.7/site-packages/django/core/management/commands/runserver.py", line 125, in inner_run
    self.check(display_num_errors=True)
  File "/usr/lib/python2.7/site-packages/django/core/management/base.py", line 359, in check
    include_deployment_checks=include_deployment_checks,
  File "/usr/lib/python2.7/site-packages/django/core/management/base.py", line 346, in _run_checks
    return checks.run_checks(**kwargs)
  File "/usr/lib/python2.7/site-packages/django/core/checks/registry.py", line 81, in run_checks
    new_errors = check(app_configs=app_configs)
  File "/usr/lib/python2.7/site-packages/django/core/checks/urls.py", line 16, in check_url_config
    return check_resolver(resolver)
  File "/usr/lib/python2.7/site-packages/django/core/checks/urls.py", line 26, in check_resolver
    return check_method()
  File "/usr/lib/python2.7/site-packages/django/urls/resolvers.py", line 254, in check
    for pattern in self.url_patterns:
  File "/usr/lib/python2.7/site-packages/django/utils/functional.py", line 35, in __get__
    res = instance.__dict__[self.name] = self.func(instance)
  File "/usr/lib/python2.7/site-packages/django/urls/resolvers.py", line 405, in url_patterns
    patterns = getattr(self.urlconf_module, "urlpatterns", self.urlconf_module)
  File "/usr/lib/python2.7/site-packages/django/utils/functional.py", line 35, in __get__
    res = instance.__dict__[self.name] = self.func(instance)
  File "/usr/lib/python2.7/site-packages/django/urls/resolvers.py", line 398, in urlconf_module
    return import_module(self.urlconf_name)
  File "/usr/lib/python2.7/importlib/__init__.py", line 37, in import_module
    __import__(name)
  File "/volume1/homes/hcyuser/www/blog/blog/urls.py", line 20, in <module>
    from cssapayment.views import paymentdetail
  File "/volume1/homes/hcyuser/www/blog/cssapayment/views.py", line 13, in <module>
    class PaymentForm(forms.ModelForm):
  File "/volume1/homes/hcyuser/www/blog/cssapayment/views.py", line 14, in PaymentForm
    class Meta:
  File "/volume1/homes/hcyuser/www/blog/cssapayment/views.py", line 15, in Meta
    model = Article
NameError: name 'Article' is not defined
Unhandled exception in thread started by <function wrapper at 0xb62e9ca4>
Performing system checks...

Traceback (most recent call last):
  File "/usr/lib/python2.7/site-packages/django/utils/autoreload.py", line 227, in wrapper
    fn(*args, **kwargs)
  File "/usr/lib/python2.7/site-packages/django/core/management/commands/runserver.py", line 125, in inner_run
    self.check(display_num_errors=True)
  File "/usr/lib/python2.7/site-packages/django/core/management/base.py", line 359, in check
    include_deployment_checks=include_deployment_checks,
  File "/usr/lib/python2.7/site-packages/django/core/management/base.py", line 346, in _run_checks
    return checks.run_checks(**kwargs)
  File "/usr/lib/python2.7/site-packages/django/core/checks/registry.py", line 81, in run_checks
    new_errors = check(app_configs=app_configs)
  File "/usr/lib/python2.7/site-packages/django/core/checks/urls.py", line 16, in check_url_config
    return check_resolver(resolver)
  File "/usr/lib/python2.7/site-packages/django/core/checks/urls.py", line 26, in check_resolver
    return check_method()
  File "/usr/lib/python2.7/site-packages/django/urls/resolvers.py", line 254, in check
    for pattern in self.url_patterns:
  File "/usr/lib/python2.7/site-packages/django/utils/functional.py", line 35, in __get__
    res = instance.__dict__[self.name] = self.func(instance)
  File "/usr/lib/python2.7/site-packages/django/urls/resolvers.py", line 405, in url_patterns
    patterns = getattr(self.urlconf_module, "urlpatterns", self.urlconf_module)
  File "/usr/lib/python2.7/site-packages/django/utils/functional.py", line 35, in __get__
    res = instance.__dict__[self.name] = self.func(instance)
  File "/usr/lib/python2.7/site-packages/django/urls/resolvers.py", line 398, in urlconf_module
    return import_module(self.urlconf_name)
  File "/usr/lib/python2.7/importlib/__init__.py", line 37, in import_module
    __import__(name)
  File "/volume1/homes/hcyuser/www/blog/blog/urls.py", line 20, in <module>
    from cssapayment.views import paymentdetail
  File "/volume1/homes/hcyuser/www/blog/cssapayment/views.py", line 13, in <module>
    class PaymentForm(forms.ModelForm):
  File "/usr/lib/python2.7/site-packages/django/forms/models.py", line 272, in __new__
    raise FieldError(message)
django.core.exceptions.FieldError: Unknown field(s) (content, title) specified for Payment
Unhandled exception in thread started by <function wrapper at 0xb633f9cc>
Traceback (most recent call last):
  File "/usr/lib/python2.7/site-packages/django/utils/autoreload.py", line 227, in wrapper
    fn(*args, **kwargs)
  File "/usr/lib/python2.7/site-packages/django/core/management/commands/runserver.py", line 117, in inner_run
    autoreload.raise_last_exception()
  File "/usr/lib/python2.7/site-packages/django/utils/autoreload.py", line 250, in raise_last_exception
    six.reraise(*_exception)
  File "/usr/lib/python2.7/site-packages/django/utils/autoreload.py", line 227, in wrapper
    fn(*args, **kwargs)
  File "/usr/lib/python2.7/site-packages/django/__init__.py", line 27, in setup
    apps.populate(settings.INSTALLED_APPS)
  File "/usr/lib/python2.7/site-packages/django/apps/registry.py", line 108, in populate
    app_config.import_models()
  File "/usr/lib/python2.7/site-packages/django/apps/config.py", line 202, in import_models
    self.models_module = import_module(models_module_name)
  File "/usr/lib/python2.7/importlib/__init__.py", line 37, in import_module
    __import__(name)
  File "/usr/lib/python2.7/site-packages/django/contrib/auth/models.py", line 103, in <module>
    class Group(models.Model):
  File "/usr/lib/python2.7/site-packages/django/db/models/base.py", line 162, in __new__
    new_class.add_to_class(obj_name, obj)
  File "/usr/lib/python2.7/site-packages/django/db/models/base.py", line 331, in add_to_class
    value.contribute_to_class(cls, name)
  File "/usr/lib/python2.7/site-packages/django/db/models/fields/related.py", line 1648, in contribute_to_class
    self.remote_field.through = create_many_to_many_intermediary_model(self, cls)
  File "/usr/lib/python2.7/site-packages/django/db/models/fields/related.py", line 1104, in create_many_to_many_intermediary_model
    'verbose_name': _('%(from)s-%(to)s relationship') % {'from': from_, 'to': to},
  File "/usr/lib/python2.7/site-packages/django/utils/functional.py", line 162, in __mod__
    return six.text_type(self) % rhs
  File "/usr/lib/python2.7/site-packages/django/utils/functional.py", line 119, in __text_cast
    return func(*self.__args, **self.__kw)
  File "/usr/lib/python2.7/site-packages/django/utils/translation/__init__.py", line 89, in ugettext
    return _trans.ugettext(message)
  File "/usr/lib/python2.7/site-packages/django/utils/translation/trans_real.py", line 345, in ugettext
    return do_translate(message, 'ugettext')
  File "/usr/lib/python2.7/site-packages/django/utils/translation/trans_real.py", line 321, in do_translate
    _default = _default or translation(settings.LANGUAGE_CODE)
  File "/usr/lib/python2.7/site-packages/django/utils/translation/trans_real.py", line 228, in translation
    _translations[language] = DjangoTranslation(language)
  File "/usr/lib/python2.7/site-packages/django/utils/translation/trans_real.py", line 134, in __init__
    raise IOError("No translation files found for default language %s." % settings.LANGUAGE_CODE)
IOError: No translation files found for default language zh-tw.
Not Found: /
[31/Jul/2017 15:28:55] "GET / HTTP/1.1" 404 2293
Internal Server Error: /article/2/
Traceback (most recent call last):
  File "/usr/lib/python2.7/site-packages/django/core/handlers/exception.py", line 41, in inner
    response = get_response(request)
  File "/usr/lib/python2.7/site-packages/django/core/handlers/base.py", line 187, in _get_response
    response = self.process_exception_by_middleware(e, request)
  File "/usr/lib/python2.7/site-packages/django/core/handlers/base.py", line 185, in _get_response
    response = wrapped_callback(request, *callback_args, **callback_kwargs)
  File "/volume1/homes/hcyuser/www/blog/article/views.py", line 14, in detail
    article = Article.objects.get(pk=int(pk))
  File "/usr/lib/python2.7/site-packages/django/db/models/manager.py", line 85, in manager_method
    return getattr(self.get_queryset(), name)(*args, **kwargs)
  File "/usr/lib/python2.7/site-packages/django/db/models/query.py", line 380, in get
    self.model._meta.object_name
DoesNotExist: Article matching query does not exist.
[31/Jul/2017 15:28:59] "GET /static/admin/css/login.css HTTP/1.1" 304 0
[31/Jul/2017 15:28:59] "GET /article/2/ HTTP/1.1" 500 70031
[31/Jul/2017 15:28:59] "GET /admin/logout/ HTTP/1.1" 302 0
[31/Jul/2017 15:28:59] "GET /admin/ HTTP/1.1" 302 0
[31/Jul/2017 15:28:59] "GET /admin/logout/ HTTP/1.1" 200 1010
[31/Jul/2017 15:28:59] "GET /admin/login/?next=/admin/ HTTP/1.1" 200 1650
[31/Jul/2017 15:29:04] "POST /admin/login/?next=/admin/ HTTP/1.1" 302 0
[31/Jul/2017 15:29:05] "GET /admin/ HTTP/1.1" 200 7338
Performing system checks...

System check identified no issues (0 silenced).
July 31, 2017 - 15:28:43
Django version 1.11.3, using settings 'blog.settings'
Starting development server at http://192.168.1.99:8000/
Quit the server with CONTROL-C.
Performing system checks...

System check identified no issues (0 silenced).
July 31, 2017 - 15:31:53
Django version 1.11.3, using settings 'blog.settings'
Starting development server at http://192.168.1.99:8000/
Quit the server with CONTROL-C.
Not Found: /
[31/Jul/2017 15:32:11] "GET / HTTP/1.1" 404 2410
Not Found: /
[31/Jul/2017 15:32:14] "GET / HTTP/1.1" 404 2410
Not Found: /
[31/Jul/2017 15:32:15] "GET / HTTP/1.1" 404 2410
Not Found: /
[31/Jul/2017 15:32:15] "GET / HTTP/1.1" 404 2410
Not Found: /
[31/Jul/2017 15:32:15] "GET / HTTP/1.1" 404 2410
Not Found: /
[31/Jul/2017 15:32:21] "GET / HTTP/1.1" 404 2410
[31/Jul/2017 15:32:30] "GET /payment/create HTTP/1.1" 301 0
[31/Jul/2017 15:32:31] "GET /payment/create/ HTTP/1.1" 200 1694
[31/Jul/2017 15:33:09] "POST /payment/create/ HTTP/1.1" 302 0
[31/Jul/2017 15:33:09] "GET /payment/2 HTTP/1.1" 301 0
[31/Jul/2017 15:33:09] "GET /payment/2/ HTTP/1.1" 200 160
Not Found: /
[31/Jul/2017 15:33:24] "GET / HTTP/1.1" 404 2410
[31/Jul/2017 15:33:25] "GET /admin/ HTTP/1.1" 200 7338
[31/Jul/2017 15:33:25] "GET /admin/ HTTP/1.1" 200 7338
[31/Jul/2017 15:33:30] "GET /admin/cssapayment/payment/ HTTP/1.1" 200 4442
[31/Jul/2017 15:33:30] "GET /static/admin/js/admin/RelatedObjectLookups.js HTTP/1.1" 304 0
[31/Jul/2017 15:33:30] "GET /admin/jsi18n/ HTTP/1.1" 200 3217
[31/Jul/2017 15:33:30] "GET /static/admin/js/vendor/jquery/jquery.js HTTP/1.1" 304 0
[31/Jul/2017 15:33:30] "GET /static/admin/js/actions.js HTTP/1.1" 304 0
[31/Jul/2017 15:33:30] "GET /static/admin/js/core.js HTTP/1.1" 304 0
[31/Jul/2017 15:33:30] "GET /static/admin/js/jquery.init.js HTTP/1.1" 304 0
[31/Jul/2017 15:33:30] "GET /static/admin/js/urlify.js HTTP/1.1" 304 0
[31/Jul/2017 15:33:30] "GET /static/admin/js/prepopulate.js HTTP/1.1" 304 0
[31/Jul/2017 15:33:30] "GET /static/admin/js/vendor/xregexp/xregexp.js HTTP/1.1" 304 0
[31/Jul/2017 15:33:31] "GET /admin/cssapayment/payment/2/change/ HTTP/1.1" 200 7221
[31/Jul/2017 15:33:32] "GET /admin/jsi18n/ HTTP/1.1" 200 3217
[31/Jul/2017 15:33:41] "GET /admin/cssapayment/payment/ HTTP/1.1" 200 4442
[31/Jul/2017 15:33:42] "GET /admin/jsi18n/ HTTP/1.1" 200 3217
[31/Jul/2017 15:33:44] "GET /admin/cssapayment/payment/1/change/ HTTP/1.1" 200 7225
[31/Jul/2017 15:33:44] "GET /admin/jsi18n/ HTTP/1.1" 200 3217
[31/Jul/2017 15:33:52] "GET /admin/cssapayment/payment/ HTTP/1.1" 200 4442
[31/Jul/2017 15:33:52] "GET /admin/jsi18n/ HTTP/1.1" 200 3217
[31/Jul/2017 15:34:43] "GET /admin/cssapayment/payment/2/change/ HTTP/1.1" 200 7221
[31/Jul/2017 15:34:45] "GET /admin/cssapayment/payment/ HTTP/1.1" 200 4442
[31/Jul/2017 15:34:47] "GET /admin/ HTTP/1.1" 200 7338
Not Found: /
[31/Jul/2017 15:34:52] "GET / HTTP/1.1" 404 2410
Internal Server Error: /payment/3/
Traceback (most recent call last):
  File "/usr/lib/python2.7/site-packages/django/core/handlers/exception.py", line 41, in inner
    response = get_response(request)
  File "/usr/lib/python2.7/site-packages/django/core/handlers/base.py", line 187, in _get_response
    response = self.process_exception_by_middleware(e, request)
  File "/usr/lib/python2.7/site-packages/django/core/handlers/base.py", line 185, in _get_response
    response = wrapped_callback(request, *callback_args, **callback_kwargs)
  File "/volume1/homes/hcyuser/www/blog/cssapayment/views.py", line 10, in paymentdetail
    pay = Payment.objects.get(pk=int(pk))
  File "/usr/lib/python2.7/site-packages/django/db/models/manager.py", line 85, in manager_method
    return getattr(self.get_queryset(), name)(*args, **kwargs)
  File "/usr/lib/python2.7/site-packages/django/db/models/query.py", line 380, in get
    self.model._meta.object_name
DoesNotExist: Payment matching query does not exist.
[31/Jul/2017 15:34:54] "GET /payment/3/ HTTP/1.1" 500 70020
Internal Server Error: /payment/3/
Traceback (most recent call last):
  File "/usr/lib/python2.7/site-packages/django/core/handlers/exception.py", line 41, in inner
    response = get_response(request)
  File "/usr/lib/python2.7/site-packages/django/core/handlers/base.py", line 187, in _get_response
    response = self.process_exception_by_middleware(e, request)
  File "/usr/lib/python2.7/site-packages/django/core/handlers/base.py", line 185, in _get_response
    response = wrapped_callback(request, *callback_args, **callback_kwargs)
  File "/volume1/homes/hcyuser/www/blog/cssapayment/views.py", line 10, in paymentdetail
    pay = Payment.objects.get(pk=int(pk))
  File "/usr/lib/python2.7/site-packages/django/db/models/manager.py", line 85, in manager_method
    return getattr(self.get_queryset(), name)(*args, **kwargs)
  File "/usr/lib/python2.7/site-packages/django/db/models/query.py", line 380, in get
    self.model._meta.object_name
DoesNotExist: Payment matching query does not exist.
[31/Jul/2017 15:34:54] "GET /payment/3/ HTTP/1.1" 500 70020
Internal Server Error: /payment/23/
Traceback (most recent call last):
  File "/usr/lib/python2.7/site-packages/django/core/handlers/exception.py", line 41, in inner
    response = get_response(request)
  File "/usr/lib/python2.7/site-packages/django/core/handlers/base.py", line 187, in _get_response
    response = self.process_exception_by_middleware(e, request)
  File "/usr/lib/python2.7/site-packages/django/core/handlers/base.py", line 185, in _get_response
    response = wrapped_callback(request, *callback_args, **callback_kwargs)
  File "/volume1/homes/hcyuser/www/blog/cssapayment/views.py", line 10, in paymentdetail
    pay = Payment.objects.get(pk=int(pk))
  File "/usr/lib/python2.7/site-packages/django/db/models/manager.py", line 85, in manager_method
    return getattr(self.get_queryset(), name)(*args, **kwargs)
  File "/usr/lib/python2.7/site-packages/django/db/models/query.py", line 380, in get
    self.model._meta.object_name
DoesNotExist: Payment matching query does not exist.
[31/Jul/2017 15:34:58] "GET /payment/23/ HTTP/1.1" 500 70038
Internal Server Error: /payment/23/
Traceback (most recent call last):
  File "/usr/lib/python2.7/site-packages/django/core/handlers/exception.py", line 41, in inner
    response = get_response(request)
  File "/usr/lib/python2.7/site-packages/django/core/handlers/base.py", line 187, in _get_response
    response = self.process_exception_by_middleware(e, request)
  File "/usr/lib/python2.7/site-packages/django/core/handlers/base.py", line 185, in _get_response
    response = wrapped_callback(request, *callback_args, **callback_kwargs)
  File "/volume1/homes/hcyuser/www/blog/cssapayment/views.py", line 10, in paymentdetail
    pay = Payment.objects.get(pk=int(pk))
  File "/usr/lib/python2.7/site-packages/django/db/models/manager.py", line 85, in manager_method
    return getattr(self.get_queryset(), name)(*args, **kwargs)
  File "/usr/lib/python2.7/site-packages/django/db/models/query.py", line 380, in get
    self.model._meta.object_name
DoesNotExist: Payment matching query does not exist.
[31/Jul/2017 15:35:00] "GET /payment/2 HTTP/1.1" 301 0
[31/Jul/2017 15:35:01] "GET /payment/2/ HTTP/1.1" 200 199
[31/Jul/2017 15:35:01] "GET /payment/23/ HTTP/1.1" 500 70038
Performing system checks...

System check identified no issues (0 silenced).
July 31, 2017 - 15:32:04
Django version 1.11.3, using settings 'blog.settings'
Starting development server at http://192.168.1.99:8000/
Quit the server with CONTROL-C.
Performing system checks...

System check identified no issues (0 silenced).
July 31, 2017 - 15:36:11
Django version 1.11.3, using settings 'blog.settings'
Starting development server at http://192.168.1.99:8000/
Quit the server with CONTROL-C.
Performing system checks...

System check identified no issues (0 silenced).
July 31, 2017 - 15:36:25
Django version 1.11.3, using settings 'blog.settings'
Starting development server at http://192.168.1.99:8000/
Quit the server with CONTROL-C.
Not Found: /
[31/Jul/2017 15:37:19] "GET / HTTP/1.1" 404 2410
Not Found: /
[31/Jul/2017 15:37:22] "GET / HTTP/1.1" 404 2410
[31/Jul/2017 15:37:23] "GET /admin/ HTTP/1.1" 200 7761
[31/Jul/2017 15:37:23] "GET /admin/ HTTP/1.1" 200 7761
Internal Server Error: /admin/cssapayment/category/
Traceback (most recent call last):
  File "/usr/lib/python2.7/site-packages/django/core/handlers/exception.py", line 41, in inner
    response = get_response(request)
  File "/usr/lib/python2.7/site-packages/django/core/handlers/base.py", line 187, in _get_response
    response = self.process_exception_by_middleware(e, request)
  File "/usr/lib/python2.7/site-packages/django/core/handlers/base.py", line 185, in _get_response
    response = wrapped_callback(request, *callback_args, **callback_kwargs)
  File "/usr/lib/python2.7/site-packages/django/contrib/admin/options.py", line 551, in wrapper
    return self.admin_site.admin_view(view)(*args, **kwargs)
  File "/usr/lib/python2.7/site-packages/django/utils/decorators.py", line 149, in _wrapped_view
    response = view_func(request, *args, **kwargs)
  File "/usr/lib/python2.7/site-packages/django/views/decorators/cache.py", line 57, in _wrapped_view_func
    response = view_func(request, *args, **kwargs)
  File "/usr/lib/python2.7/site-packages/django/contrib/admin/sites.py", line 224, in inner
    return view(request, *args, **kwargs)
  File "/usr/lib/python2.7/site-packages/django/utils/decorators.py", line 67, in _wrapper
    return bound_func(*args, **kwargs)
  File "/usr/lib/python2.7/site-packages/django/utils/decorators.py", line 149, in _wrapped_view
    response = view_func(request, *args, **kwargs)
  File "/usr/lib/python2.7/site-packages/django/utils/decorators.py", line 63, in bound_func
    return func.__get__(self, type(self))(*args2, **kwargs2)
  File "/usr/lib/python2.7/site-packages/django/contrib/admin/options.py", line 1542, in changelist_view
    self.list_max_show_all, self.list_editable, self,
  File "/usr/lib/python2.7/site-packages/django/contrib/admin/views/main.py", line 79, in __init__
    self.get_results(request)
  File "/usr/lib/python2.7/site-packages/django/contrib/admin/views/main.py", line 177, in get_results
    result_count = paginator.count
  File "/usr/lib/python2.7/site-packages/django/utils/functional.py", line 35, in __get__
    res = instance.__dict__[self.name] = self.func(instance)
  File "/usr/lib/python2.7/site-packages/django/core/paginator.py", line 79, in count
    return self.object_list.count()
  File "/usr/lib/python2.7/site-packages/django/db/models/query.py", line 364, in count
    return self.query.get_count(using=self.db)
  File "/usr/lib/python2.7/site-packages/django/db/models/sql/query.py", line 499, in get_count
    number = obj.get_aggregation(using, ['__count'])['__count']
  File "/usr/lib/python2.7/site-packages/django/db/models/sql/query.py", line 480, in get_aggregation
    result = compiler.execute_sql(SINGLE)
  File "/usr/lib/python2.7/site-packages/django/db/models/sql/compiler.py", line 886, in execute_sql
    raise original_exception
OperationalError: no such table: cssapayment_category
[31/Jul/2017 15:37:28] "GET /admin/cssapayment/category/ HTTP/1.1" 500 129857
Internal Server Error: /admin/cssapayment/category/
Traceback (most recent call last):
  File "/usr/lib/python2.7/site-packages/django/core/handlers/exception.py", line 41, in inner
    response = get_response(request)
  File "/usr/lib/python2.7/site-packages/django/core/handlers/base.py", line 187, in _get_response
    response = self.process_exception_by_middleware(e, request)
  File "/usr/lib/python2.7/site-packages/django/core/handlers/base.py", line 185, in _get_response
    response = wrapped_callback(request, *callback_args, **callback_kwargs)
  File "/usr/lib/python2.7/site-packages/django/contrib/admin/options.py", line 551, in wrapper
    return self.admin_site.admin_view(view)(*args, **kwargs)
  File "/usr/lib/python2.7/site-packages/django/utils/decorators.py", line 149, in _wrapped_view
    response = view_func(request, *args, **kwargs)
  File "/usr/lib/python2.7/site-packages/django/views/decorators/cache.py", line 57, in _wrapped_view_func
    response = view_func(request, *args, **kwargs)
  File "/usr/lib/python2.7/site-packages/django/contrib/admin/sites.py", line 224, in inner
    return view(request, *args, **kwargs)
  File "/usr/lib/python2.7/site-packages/django/utils/decorators.py", line 67, in _wrapper
    return bound_func(*args, **kwargs)
  File "/usr/lib/python2.7/site-packages/django/utils/decorators.py", line 149, in _wrapped_view
    response = view_func(request, *args, **kwargs)
  File "/usr/lib/python2.7/site-packages/django/utils/decorators.py", line 63, in bound_func
    return func.__get__(self, type(self))(*args2, **kwargs2)
  File "/usr/lib/python2.7/site-packages/django/contrib/admin/options.py", line 1542, in changelist_view
    self.list_max_show_all, self.list_editable, self,
  File "/usr/lib/python2.7/site-packages/django/contrib/admin/views/main.py", line 79, in __init__
    self.get_results(request)
  File "/usr/lib/python2.7/site-packages/django/contrib/admin/views/main.py", line 177, in get_results
    result_count = paginator.count
  File "/usr/lib/python2.7/site-packages/django/utils/functional.py", line 35, in __get__
    res = instance.__dict__[self.name] = self.func(instance)
  File "/usr/lib/python2.7/site-packages/django/core/paginator.py", line 79, in count
    return self.object_list.count()
  File "/usr/lib/python2.7/site-packages/django/db/models/query.py", line 364, in count
    return self.query.get_count(using=self.db)
  File "/usr/lib/python2.7/site-packages/django/db/models/sql/query.py", line 499, in get_count
    number = obj.get_aggregation(using, ['__count'])['__count']
  File "/usr/lib/python2.7/site-packages/django/db/models/sql/query.py", line 480, in get_aggregation
    result = compiler.execute_sql(SINGLE)
  File "/usr/lib/python2.7/site-packages/django/db/models/sql/compiler.py", line 886, in execute_sql
    raise original_exception
OperationalError: no such table: cssapayment_category
[31/Jul/2017 15:37:32] "GET /admin/cssapayment/category/ HTTP/1.1" 500 129857
[31/Jul/2017 15:38:19] "GET /admin/ HTTP/1.1" 200 7761
[31/Jul/2017 15:38:19] "GET /static/admin/css/base.css HTTP/1.1" 304 0
[31/Jul/2017 15:38:19] "GET /static/admin/css/dashboard.css HTTP/1.1" 304 0
[31/Jul/2017 15:38:19] "GET /static/admin/css/fonts.css HTTP/1.1" 304 0
[31/Jul/2017 15:38:21] "GET /admin/cssapayment/payment/ HTTP/1.1" 200 4442
[31/Jul/2017 15:38:21] "GET /admin/jsi18n/ HTTP/1.1" 200 3217
[31/Jul/2017 15:38:24] "GET /admin/cssapayment/payment/2/change/ HTTP/1.1" 200 8311
[31/Jul/2017 15:38:24] "GET /admin/jsi18n/ HTTP/1.1" 200 3217
[31/Jul/2017 15:38:33] "GET /admin/cssapayment/payment/ HTTP/1.1" 200 4442
[31/Jul/2017 15:38:33] "GET /admin/jsi18n/ HTTP/1.1" 200 3217
[31/Jul/2017 15:38:35] "GET /admin/cssapayment/ HTTP/1.1" 200 2695
[31/Jul/2017 15:38:37] "GET /admin/cssapayment/category/ HTTP/1.1" 200 3076
[31/Jul/2017 15:38:37] "GET /admin/jsi18n/ HTTP/1.1" 200 3217
[31/Jul/2017 15:38:39] "GET /admin/cssapayment/category/add/ HTTP/1.1" 200 3851
[31/Jul/2017 15:38:39] "GET /admin/jsi18n/ HTTP/1.1" 200 3217
[31/Jul/2017 15:38:50] "POST /admin/cssapayment/category/add/ HTTP/1.1" 302 0
[31/Jul/2017 15:38:50] "GET /admin/cssapayment/category/ HTTP/1.1" 200 4413
[31/Jul/2017 15:38:51] "GET /admin/jsi18n/ HTTP/1.1" 200 3217
[31/Jul/2017 15:38:54] "GET /admin/cssapayment/category/add/ HTTP/1.1" 200 3851
[31/Jul/2017 15:38:54] "GET /admin/jsi18n/ HTTP/1.1" 200 3217
[31/Jul/2017 15:39:00] "POST /admin/cssapayment/category/add/ HTTP/1.1" 302 0
[31/Jul/2017 15:39:00] "GET /admin/cssapayment/category/ HTTP/1.1" 200 4645
[31/Jul/2017 15:39:00] "GET /admin/jsi18n/ HTTP/1.1" 200 3217
[31/Jul/2017 15:39:03] "GET /admin/cssapayment/ HTTP/1.1" 200 2695
[31/Jul/2017 15:39:06] "GET /admin/ HTTP/1.1" 200 7774
[31/Jul/2017 15:39:14] "GET /admin/auth/ HTTP/1.1" 200 2707
[31/Jul/2017 15:39:24] "GET /admin/cssapayment/category/ HTTP/1.1" 200 4453
[31/Jul/2017 15:39:24] "GET /admin/jsi18n/ HTTP/1.1" 200 3217
[31/Jul/2017 15:39:27] "GET /admin/cssapayment/ HTTP/1.1" 200 2695
Not Found: /cssapayment/
[31/Jul/2017 15:39:48] "GET /cssapayment/ HTTP/1.1" 404 2464
Not Found: /cssapayment/
[31/Jul/2017 15:39:52] "GET /cssapayment/ HTTP/1.1" 404 2464
Not Found: /cssapayment/
[31/Jul/2017 15:39:54] "GET /cssapayment/ HTTP/1.1" 404 2464
Not Found: /cssapayment/1/
[31/Jul/2017 15:39:55] "GET /cssapayment/1/ HTTP/1.1" 404 2470
Not Found: /cssapayment/2/
[31/Jul/2017 15:39:59] "GET /cssapayment/2/ HTTP/1.1" 404 2470
Not Found: /cssapayment/3/
[31/Jul/2017 15:40:03] "GET /cssapayment/3/ HTTP/1.1" 404 2470
[31/Jul/2017 15:40:12] "GET /admin/cssapayment/ HTTP/1.1" 200 2695
[31/Jul/2017 15:40:15] "GET /admin/cssapayment/payment/ HTTP/1.1" 200 4442
[31/Jul/2017 15:40:15] "GET /admin/jsi18n/ HTTP/1.1" 200 3217
[31/Jul/2017 15:40:16] "GET /admin/cssapayment/payment/2/change/ HTTP/1.1" 200 8391
[31/Jul/2017 15:40:16] "GET /admin/jsi18n/ HTTP/1.1" 200 3217
Not Found: /cssapayment/payment/2
[31/Jul/2017 15:40:27] "GET /cssapayment/payment/2 HTTP/1.1" 404 2491
Not Found: /cssapayment/2
[31/Jul/2017 15:40:33] "GET /cssapayment/2 HTTP/1.1" 404 2467
Not Found: /cssapayment/2/
[31/Jul/2017 15:40:33] "GET /cssapayment/2/ HTTP/1.1" 404 2470
[31/Jul/2017 15:40:40] "GET /payment/2/ HTTP/1.1" 200 199
[31/Jul/2017 15:40:40] "GET /payment/2/ HTTP/1.1" 200 199
[31/Jul/2017 15:40:46] "GET /payment/create HTTP/1.1" 301 0
[31/Jul/2017 15:40:46] "GET /payment/create/ HTTP/1.1" 200 1694
Not Found: /payment/
[31/Jul/2017 15:41:00] "GET /payment/ HTTP/1.1" 404 2452
Not Found: /payment/
[31/Jul/2017 15:41:01] "GET /payment/ HTTP/1.1" 404 2452
